Workbook

Sheet MonthlyMetric
A1: Tutor Name | B1: Date Range | C1: % to Delivery Target | D1: % to Availability Target | E1: % Sessions on Time | F1: % Parents Updates Done on Time | G1: % of Active Students with Progress Updates Completed in last 2 months | H1: Weighted Repurchases | I1: OLD PPW | J1: Ratio of PPW Events with Attached PPWs | K1: Tier | L1: Adjunct/Professional | M1: Faculty Leader
A2: Aaron Schneberger | B2: 10/5/25 - 11/1/25 | C2: 1.2813 | D2: 1.1602 | E2: 1 | F2: 1 | G2: 0.90909091 | H2: 3 | I2: 2/4 | J2: 0.5 | K2: =VLOOKUP(A2,MonthlyMetricFullData!A:D,2,FALSE) -> Distinguished | L2: =IF(VLOOKUP(A2,MonthlyMetricFullData!A:E,5,FALSE)<30,"Adjunct","Professional") -> Professional | M2: =VLOOKUP(A2,MonthlyMetricFullData!A:D,3,FALSE) -> Ian Plamondon
A3: Aaron Schneberger | B3: 11/2/25 - 11/29/25 | C3: 0.76 | D3: 0.78 | E3: 1 | F3: 1 | G3: 0.91 | H3: 1 | K3: =VLOOKUP(A3,MonthlyMetricFullData!A:D,2,FALSE) -> Distinguished | L3: =IF(VLOOKUP(A3,MonthlyMetricFullData!A:E,5,FALSE)<30,"Adjunct","Professional") -> Professional | M3: =VLOOKUP(A3,MonthlyMetricFullData!A:D,3,FALSE) -> Ian Plamondon
A4: Aaron Schneberger | B4: 2/22/26 - 3/21/26 | C4: 0 | D4: 0 | E4: 0 | F4: 0 | G4: 0 | H4: 0 | I4: 0/0 | J4: 0 | K4: =VLOOKUP(A4,MonthlyMetricFullData!A:D,2,FALSE) -> Distinguished | L4: =IF(VLOOKUP(A4,MonthlyMetricFullData!A:E,5,FALSE)<30,"Adjunct","Professional") -> Professional | M4: =VLOOKUP(A4,MonthlyMetricFullData!A:D,3,FALSE) -> Ian Plamondon
A5: Aaron Schneberger | B5: 3/22/26 - 4/18/26 | C5: 0.5042 | D5: 0.9441 | E5: 1 | F5: 0.676 | H5: 1 | I5: 11/16 | J5: 0.69 | K5: =VLOOKUP(A5,MonthlyMetricFullData!A:D,2,FALSE) -> Distinguished | L5: =IF(VLOOKUP(A5,MonthlyMetricFullData!A:E,5,FALSE)<30,"Adjunct","Professional") -> Professional | M5: =VLOOKUP(A5,MonthlyMetricFullData!A:D,3,FALSE) -> Ian Plamondon
A6: Aaron Schneberger | B6: 5/18/25 - 6/14/25 | C6: 0.74 | D6: 0.9 | E6: 0.99 | F6: 1 | G6: 1 | H6: 10 | I6: 1 | J6: =I6 -> 1 | K6: =VLOOKUP(A6,MonthlyMetricFullData!A:D,2,FALSE) -> Distinguished | L6: =IF(VLOOKUP(A6,MonthlyMetricFullData!A:E,5,FALSE)<30,"Adjunct","Professional") -> Professional | M6: =VLOOKUP(A6,MonthlyMetricFullData!A:D,3,FALSE) -> Ian Plamondon
A7: Aaron Schneberger | B7: 6/15/25 - 7/12/25 | C7: 0.5 | D7: 0.81 | E7: 1 | F7: 0.93 | G7: 0.7 | H7: 2 | I7: 2/3 | J7: 0.67 | K7: =VLOOKUP(A7,MonthlyMetricFullData!A:D,2,FALSE) -> Distinguished | L7: =IF(VLOOKUP(A7,MonthlyMetricFullData!A:E,5,FALSE)<30,"Adjunct","Professional") -> Professional | M7: =VLOOKUP(A7,MonthlyMetricFullData!A:D,3,FALSE) -> Ian Plamondon
A8: Aaron Schneberger | B8: 7/13/25 - 8/10/25 | C8: 0.48 | D8: 0.5 | E8: 1 | F8: 1 | G8: 0.71 | H8: 3 | I8: 1 | J8: =I8 -> 1 | K8: =VLOOKUP(A8,MonthlyMetricFullData!A:D,2,FALSE) -> Distinguished | L8: =IF(VLOOKUP(A8,MonthlyMetricFullData!A:E,5,FALSE)<30,"Adjunct","Professional") -> Professional | M8: =VLOOKUP(A8,MonthlyMetricFullData!A:D,3,FALSE) -> Ian Plamondon
A9: Aaron Schneberger | B9: 8/10/25 - 9/6/25 | C9: 1.2 | D9: 1.24 | E9: 1 | F9: 1 | G9: 1 | H9: 4 | K9: =VLOOKUP(A9,MonthlyMetricFullData!A:D,2,FALSE) -> Distinguished | L9: =IF(VLOOKUP(A9,MonthlyMetricFullData!A:E,5,FALSE)<30,"Adjunct","Professional") -> Professional | M9: =VLOOKUP(A9,MonthlyMetricFullData!A:D,3,FALSE) -> Ian Plamondon
A10: Aaron Schneberger | B10: 9/7/25 - 10/4/25 | C10: 1.06 | D10: 1.1 | E10: 1 | F10: 0.97 | G10: 0.82 | H10: 6 | I10: 1/1 | J10: 1 | K10: =VLOOKUP(A10,MonthlyMetricFullData!A:D,2,FALSE) -> Distinguished | L10: =IF(VLOOKUP(A10,MonthlyMetricFullData!A:E,5,FALSE)<30,"Adjunct","Professional") -> Professional | M10: =VLOOKUP(A10,MonthlyMetricFullData!A:D,3,FALSE) -> Ian Plamondon
A11: Akeema Williams | B11: 1/25/26 - 2/21/26 | C11: 1.0875 | D11: 0.9704 | E11: 1 | F11: 0.90291262 | G11: 0.7826087 | H11: 16 | I11: 2/4 | J11: 0.5 | K11: =VLOOKUP(A11,MonthlyMetricFullData!A:D,2,FALSE) -> Distinguished | L11: =IF(VLOOKUP(A11,MonthlyMetricFullData!A:E,5,FALSE)<30,"Adjunct","Professional") -> Professional | M11: =VLOOKUP(A11,MonthlyMetricFullData!A:D,3,FALSE) -> Ian Plamondon
A12: Akeema Williams | B12: 10/5/25 - 11/1/25 | C12: 1.0917 | D12: 1.1118 | E12: 0.99259259 | F12: 0.97916667 | G12: 0.96153846 | H12: 14 | I12: 6/10 | J12: 0.6 | K12: =VLOOKUP(A12,MonthlyMetricFullData!A:D,2,FALSE) -> Distinguished | L12: =IF(VLOOKUP(A12,MonthlyMetricFullData!A:E,5,FALSE)<30,"Adjunct","Professional") -> Professional | M12: =VLOOKUP(A12,MonthlyMetricFullData!A:D,3,FALSE) -> Ian Plamondon
A13: Akeema Williams | B13: 11/2/25 - 11/29/25 | C13: 0.93 | D13: 0.96 | E13: 0.99 | F13: 0.97 | G13: 0.76 | H13: 11 | I13: 45664 | J13: 0.0014285714 | K13: =VLOOKUP(A13,MonthlyMetricFullData!A:D,2,FALSE) -> Distinguished | L13: =IF(VLOOKUP(A13,MonthlyMetricFullData!A:E,5,FALSE)<30,"Adjunct","Professional") -> Professional | M13: =VLOOKUP(A13,MonthlyMetricFullData!A:D,3,FALSE) -> Ian Plamondon
A14: Akeema Williams | B14: 11/30/25 - 12/27/25 | C14: 0.98 | D14: 0.98 | E14: 1 | F14: 0.95 | G14: 0.9 | H14: 19 | K14: =VLOOKUP(A14,MonthlyMetricFullData!A:D,2,FALSE) -> Distinguished | L14: =IF(VLOOKUP(A14,MonthlyMetricFullData!A:E,5,FALSE)<30,"Adjunct","Professional") -> Professional | M14: =VLOOKUP(A14,MonthlyMetricFullData!A:D,3,FALSE) -> Ian Plamondon
A15: Akeema Williams | B15: 12/28/25 - 1/25/26 | C15: 0.8958 | D15: 0.903 | E15: 1 | F15: 0.96103896 | G15: 0.95238095 | H15: 16 | I15: 0.8 | J15: =I15 -> 0.8 | K15: =VLOOKUP(A15,MonthlyMetricFullData!A:D,2,FALSE) -> Distinguished | L15: =IF(VLOOKUP(A15,MonthlyMetricFullData!A:E,5,FALSE)<30,"Adjunct","Professional") -> Professional | M15: =VLOOKUP(A15,MonthlyMetricFullData!A:D,3,FALSE) -> Ian Plamondon
A16: Akeema Williams | B16: 2/22/26 - 3/21/26 | C16: 1.01 | D16: 1.01 | E16: 1 | F16: 0.97 | G16: 0.88 | H16: 14 | I16: 0/1 | J16: 0 | K16: =VLOOKUP(A16,MonthlyMetricFullData!A:D,2,FALSE) -> Distinguished | L16: =IF(VLOOKUP(A16,MonthlyMetricFullData!A:E,5,FALSE)<30,"Adjunct","Professional") -> Professional | M16: =VLOOKUP(A16,MonthlyMetricFullData!A:D,3,FALSE) -> Ian Plamondon
A17: Akeema Williams | B17: 3/22/26 - 4/18/26 | C17: 1 | D17: 1.0066 | E17: 0.99115044 | F17: 0.961 | G17: 0.86666667 | H17: 13 | I17: 1/2 | J17: 0.5 | K17: =VLOOKUP(A17,MonthlyMetricFullData!A:D,2,FALSE) -> Distinguished | L17: =IF(VLOOKUP(A17,MonthlyMetricFullData!A:E,5,FALSE)<30,"Adjunct","Professional") -> Professional | M17: =VLOOKUP(A17,MonthlyMetricFullData!A:D,3,FALSE) -> Ian Plamondon
A18: Akeema Williams | B18: 5/18/25 - 6/14/25 | C18: 0.75 | D18: 1.01 | E18: 1 | F18: 1 | G18: 0.9 | H18: 2 | I18: 1/2 | J18: 0.5 | K18: =VLOOKUP(A18,MonthlyMetricFullData!A:D,2,FALSE) -> Distinguished | L18: =IF(VLOOKUP(A18,MonthlyMetricFullData!A:E,5,FALSE)<30,"Adjunct","Professional") -> Professional | M18: =VLOOKUP(A18,MonthlyMetricFullData!A:D,3,FALSE) -> Ian Plamondon
A19: Akeema Williams | B19: 6/15/25 - 7/12/25 | C19: 0.62 | D19: 0.92 | E19: 1 | F19: 0.77 | G19: 0.64 | H19: 2 | I19: 0 | J19: =I19 -> 0 | K19: =VLOOKUP(A19,MonthlyMetricFullData!A:D,2,FALSE) -> Distinguished | L19: =IF(VLOOKUP(A19,MonthlyMetricFullData!A:E,5,FALSE)<30,"Adjunct","Professional") -> Professional | M19: =VLOOKUP(A19,MonthlyMetricFullData!A:D,3,FALSE) -> Ian Plamondon
A20: Akeema Williams | B20: 7/13/25 - 8/10/25 | C20: 0.94 | D20: 0.98 | E20: 0.99 | F20: 1 | G20: 0.46 | H20: 6 | I20: 2/3 | J20: 0.67 | K20: =VLOOKUP(A20,MonthlyMetricFullData!A:D,2,FALSE) -> Distinguished | L20: =IF(VLOOKUP(A20,MonthlyMetricFullData!A:E,5,FALSE)<30,"Adjunct","Professional") -> Professional | M20: =VLOOKUP(A20,MonthlyMetricFullData!A:D,3,FALSE) -> Ian Plamondon
A21: Akeema Williams | B21: 8/10/25 - 9/6/25 | C21: 0.8 | D21: 0.97 | E21: 1 | F21: 0.99 | G21: 0.91 | H21: 10 | I21: 1/3 | J21: 0.33 | K21: =VLOOKUP(A21,MonthlyMetricFullData!A:D,2,FALSE) -> Distinguished | L21: =IF(VLOOKUP(A21,MonthlyMetricFullData!A:E,5,FALSE)<30,"Adjunct","Professional") -> Professional | M21: =VLOOKUP(A21,MonthlyMetricFullData!A:D,3,FALSE) -> Ian Plamondon
A22: Akeema Williams | B22: 9/7/25 - 10/4/25 | C22: 0.96 | D22: 1.01 | E22: 0.99 | F22: 0.97 | G22: 0.74 | H22: 13 | I22: 4/6 | J22: 0.67 | K22: =VLOOKUP(A22,MonthlyMetricFullData!A:D,2,FALSE) -> Distinguished | L22: =IF(VLOOKUP(A22,MonthlyMetricFullData!A:E,5,FALSE)<30,"Adjunct","Professional") -> Professional | M22: =VLOOKUP(A22,MonthlyMetricFullData!A:D,3,FALSE) -> Ian Plamondon
A23: Akshiv Gulati | B23: 1/25/26 - 2/21/26 | C23: 0.2952 | D23: 0.686 | E23: 0.84 | F23: 0.84210526 | G23: 0 | H23: 0 | I23: 1/6 | J23: 0.17 | K23: =VLOOKUP(A23,MonthlyMetricFullData!A:D,2,FALSE) -> #N/A | L23: =IF(VLOOKUP(A23,MonthlyMetricFullData!A:E,5,FALSE)<30,"Adjunct","Professional") -> #N/A | M23: =VLOOKUP(A23,MonthlyMetricFullData!A:D,3,FALSE) -> #N/A
A24: Akshiv Gulati | B24: 2/22/26 - 3/21/26 | C24: 1.04 | D24: 1.16 | E24: 0.97 | F24: 0.88 | G24: 0.29 | H24: 3 | I24: 1/19 | J24: =1/19 -> 0.052631579 | K24: =VLOOKUP(A24,MonthlyMetricFullData!A:D,2,FALSE) -> #N/A | L24: =IF(VLOOKUP(A24,MonthlyMetricFullData!A:E,5,FALSE)<30,"Adjunct","Professional") -> #N/A | M24: =VLOOKUP(A24,MonthlyMetricFullData!A:D,3,FALSE) -> #N/A
A25: Akshiv Gulati | B25: 3/22/26 - 4/18/26 | C25: 0.9143 | D25: 0.8416 | E25: 1 | F25: 0.833 | G25: 0.76923077 | H25: 15 | I25: 2/9 | J25: 0.22 | K25: =VLOOKUP(A25,MonthlyMetricFullData!A:D,2,FALSE) -> #N/A | L25: =IF(VLOOKUP(A25,MonthlyMetricFullData!A:E,5,FALSE)<30,"Adjunct","Professional") -> #N/A | M25: =VLOOKUP(A25,MonthlyMetricFullData!A:D,3,FALSE) -> #N/A
A26: Alex Small | B26: 1/25/26 - 2/21/26 | C26: 1.2188 | D26: 1.4063 | E26: 1 | F26: 0.96551724 | G26: 0.57142857 | H26: 3 | I26: 1/2 | J26: 0.5 | K26: =VLOOKUP(A26,MonthlyMetricFullData!A:D,2,FALSE) -> Premium | L26: =IF(VLOOKUP(A26,MonthlyMetricFullData!A:E,5,FALSE)<30,"Adjunct","Professional") -> Adjunct | M26: =VLOOKUP(A26,MonthlyMetricFullData!A:D,3,FALSE) -> Ela Cross
A27: Alex Small | B27: 10/5/25 - 11/1/25 | C27: 0.9688 | D27: 1.5156 | E27: 1 | F27: 1 | G27: 0.5 | H27: 3 | I27: 1/1 | J27: 1 | K27: =VLOOKUP(A27,MonthlyMetricFullData!A:D,2,FALSE) -> Premium | L27: =IF(VLOOKUP(A27,MonthlyMetricFullData!A:E,5,FALSE)<30,"Adjunct","Professional") -> Adjunct | M27: =VLOOKUP(A27,MonthlyMetricFullData!A:D,3,FALSE) -> Ela Cross
A28: Alex Small | B28: 11/2/25 - 11/29/25 | C28: 0.8 | D28: 1.54 | E28: 1 | F28: 0.9 | G28: 0.88 | H28: 2 | K28: =VLOOKUP(A28,MonthlyMetricFullData!A:D,2,FALSE) -> Premium | L28: =IF(VLOOKUP(A28,MonthlyMetricFullData!A:E,5,FALSE)<30,"Adjunct","Professional") -> Adjunct | M28: =VLOOKUP(A28,MonthlyMetricFullData!A:D,3,FALSE) -> Ela Cross
A29: Alex Small | B29: 11/30/25 - 12/27/25 | C29: 0.35 | D29: 1.4 | E29: 1 | F29: 0.91 | G29: 0.67 | H29: 0 | K29: =VLOOKUP(A29,MonthlyMetricFullData!A:D,2,FALSE) -> Premium | L29: =IF(VLOOKUP(A29,MonthlyMetricFullData!A:E,5,FALSE)<30,"Adjunct","Professional") -> Adjunct | M29: =VLOOKUP(A29,MonthlyMetricFullData!A:D,3,FALSE) -> Ela Cross
A30: Alex Small | B30: 12/28/25 - 1/25/26 | C30: 0.6667 | D30: 1.4531 | E30: 1 | F30: 1 | G30: 0 | H30: 2 | I30: 0/0 | J30: 0 | K30: =VLOOKUP(A30,MonthlyMetricFullData!A:D,2,FALSE) -> Premium | L30: =IF(VLOOKUP(A30,MonthlyMetricFullData!A:E,5,FALSE)<30,"Adjunct","Professional") -> Adjunct | M30: =VLOOKUP(A30,MonthlyMetricFullData!A:D,3,FALSE) -> Ela Cross
A31: Alex Small | B31: 2/22/26 - 3/21/26 | C31: 1.33 | D31: 1.29 | E31: 1 | F31: 1 | G31: 0.57 | H31: 2 | I31: 1/1 | J31: 1 | K31: =VLOOKUP(A31,MonthlyMetricFullData!A:D,2,FALSE) -> Premium | L31: =IF(VLOOKUP(A31,MonthlyMetricFullData!A:E,5,FALSE)<30,"Adjunct","Professional") -> Adjunct | M31: =VLOOKUP(A31,MonthlyMetricFullData!A:D,3,FALSE) -> Ela Cross
A32: Alex Small | B32: 3/22/26 - 4/18/26 | C32: 1.1979 | D32: 1.3125 | E32: 1 | F32: 0.694 | G32: 0.22222222 | H32: 3 | K32: =VLOOKUP(A32,MonthlyMetricFullData!A:D,2,FALSE) -> Premium | L32: =IF(VLOOKUP(A32,MonthlyMetricFullData!A:E,5,FALSE)<30,"Adjunct","Professional") -> Adjunct | M32: =VLOOKUP(A32,MonthlyMetricFullData!A:D,3,FALSE) -> Ela Cross
A33: Alex Small | B33: 5/18/25 - 6/14/25 | C33: 0.31 | D33: 1 | E33: 1 | F33: 0.6 | G33: #N/A | H33: 1 | K33: =VLOOKUP(A33,MonthlyMetricFullData!A:D,2,FALSE) -> Premium | L33: =IF(VLOOKUP(A33,MonthlyMetricFullData!A:E,5,FALSE)<30,"Adjunct","Professional") -> Adjunct | M33: =VLOOKUP(A33,MonthlyMetricFullData!A:D,3,FALSE) -> Ela Cross
A34: Alex Small | B34: 6/15/25 - 7/12/25 | C34: 0 | D34: 0.79 | E34: 0 | F34: 0 | G34: 0 | H34: #N/A | K34: =VLOOKUP(A34,MonthlyMetricFullData!A:D,2,FALSE) -> Premium | L34: =IF(VLOOKUP(A34,MonthlyMetricFullData!A:E,5,FALSE)<30,"Adjunct","Professional") -> Adjunct | M34: =VLOOKUP(A34,MonthlyMetricFullData!A:D,3,FALSE) -> Ela Cross
A35: Alex Small | B35: 7/13/25 - 8/10/25 | C35: 0 | D35: 1 | E35: 0 | F35: 0 | G35: 0 | H35: #N/A | K35: =VLOOKUP(A35,MonthlyMetricFullData!A:D,2,FALSE) -> Premium | L35: =IF(VLOOKUP(A35,MonthlyMetricFullData!A:E,5,FALSE)<30,"Adjunct","Professional") -> Adjunct | M35: =VLOOKUP(A35,MonthlyMetricFullData!A:D,3,FALSE) -> Ela Cross
A36: Alex Small | B36: 8/10/25 - 9/6/25 | C36: 0.76 | D36: 1.42 | E36: 1 | F36: 1 | G36: 0 | H36: 2 | I36: 3/5 | J36: 0.6 | K36: =VLOOKUP(A36,MonthlyMetricFullData!A:D,2,FALSE) -> Premium | L36: =IF(VLOOKUP(A36,MonthlyMetricFullData!A:E,5,FALSE)<30,"Adjunct","Professional") -> Adjunct | M36: =VLOOKUP(A36,MonthlyMetricFullData!A:D,3,FALSE) -> Ela Cross
A37: Alex Small | B37: 9/7/25 - 10/4/25 | C37: 1.14 | D37: 1.46 | E37: 1 | F37: 0.73 | G37: 0 | H37: 3 | K37: =VLOOKUP(A37,MonthlyMetricFullData!A:D,2,FALSE) -> Premium | L37: =IF(VLOOKUP(A37,MonthlyMetricFullData!A:E,5,FALSE)<30,"Adjunct","Professional") -> Adjunct | M37: =VLOOKUP(A37,MonthlyMetricFullData!A:D,3,FALSE) -> Ela Cross
A38: Alexa Pinera | B38: 1/25/26 - 2/21/26 | C38: 0.7542 | D38: 2.0708 | E38: 1 | F38: 1 | G38: 0.91666667 | H38: 6 | I38: 2/3 | J38: 0.66 | K38: =VLOOKUP(A38,MonthlyMetricFullData!A:D,2,FALSE) -> Premium | L38: =IF(VLOOKUP(A38,MonthlyMetricFullData!A:E,5,FALSE)<30,"Adjunct","Professional") -> Professional | M38: =VLOOKUP(A38,MonthlyMetricFullData!A:D,3,FALSE) -> Ian Plamondon
A39: Alexa Pinera | B39: 10/5/25 - 11/1/25 | C39: 0.6257 | D39: 2.2516 | E39: 0.94029851 | F39: 0.97619048 | G39: 0.75 | H39: 1 | I39: 4/4 | J39: 1 | K39: =VLOOKUP(A39,MonthlyMetricFullData!A:D,2,FALSE) -> Premium | L39: =IF(VLOOKUP(A39,MonthlyMetricFullData!A:E,5,FALSE)<30,"Adjunct","Professional") -> Professional | M39: =VLOOKUP(A39,MonthlyMetricFullData!A:D,3,FALSE) -> Ian Plamondon
A40: Alexa Pinera | B40: 11/2/25 - 11/29/25 | C40: 0.7 | D40: 1.99 | E40: 0.97 | F40: 1 | G40: 0.71 | H40: 5 | I40: 45691 | J40: 0.0066666667 | K40: =VLOOKUP(A40,MonthlyMetricFullData!A:D,2,FALSE) -> Premium | L40: =IF(VLOOKUP(A40,MonthlyMetricFullData!A:E,5,FALSE)<30,"Adjunct","Professional") -> Professional | M40: =VLOOKUP(A40,MonthlyMetricFullData!A:D,3,FALSE) -> Ian Plamondon
...

Sheet ProgressUpdateEmails
A1: update_id | B1: sent_at | C1: tutor | D1: team | E1: course_id | F1: student_name | G1: body | H1: score | J1: Row Labels | K1: Average of score
J2: Akeema Williams | K2: 3.5384615
J3: Akshiv Gulati | K3: 2
J4: Alexa Pinera | K4: 3.3333333
J5: Alexandra Berrios | K5: 3.8181818
J6: Alexis Boucher | K6: 1.8
J7: Alison Trumbull | K7: 3.5
J8: Allison Peck | K8: 5
J9: Amber Maldonado | K9: 4.75
J10: Ana Heiser | K10: 3.7142857
J11: Andres Jarquin | K11: 3.6666667
J12: Andrew Brown | K12: 3.5714286
J13: Andrew Gehlot | K13: 2.8
... J155: Zoe Shanley | K155: 3.4444444
J156: (blank)
J157: Parthav Elangovan | K157: 2.5
J158: Taryn Parks | K158: 4.6666667
J159: Syrae Jennings | K159: 5
J160: Autumn Reed | K160: 3
J161: Amelia Sain | K161: 4.6666667
J162: Nisan Hubbard | K162: 1
J163: Dehavion Knight | K163: 4.5714286
J164: Nicole Bishop | K164: 3.5
J165: Saahithi Punnam | K165: 3
J166: Faith Rogers | K166: 2.7692308
J167: Ava Robledo | K167: 3.5
J168: Daniel Olson | K168: 3
... J182: Grand Total | K182: 3.2952646

Sheet MonthlyMetricFullData
A1: 3/22/26 - 4/18/26
G2: 0.8 | J2: 1 | K2: 0.1 | L2: 0.9 | M2: 0.95 | O2: 0.8
A3: Bottom Range Lower Than | G3: 0.7 | J3: 0.8 | K3: 0.2 | L3: 0.75 | M3: 0.8 | O3: 0.5
A4: Tutor Name | B4: Current Tier | C4: Faculty Leader Name | D4: Hire Date | E4: Delivery Target | F4: Avg. Delivery Actual | G4: % to Delivery Target | H4: Availability Target | I4: Avg. Availability Actual | J4: % to Availability Target | K4: Prep Time % | L4: % Parents Updates Done on Time | M4: % Sessions on Time | N4: Ratio of PPW Events with Attached PPWs | O4: % of Active Students with Progress Updates Completed | P4: # of NPS Scores | Q4: Avg. NPS Score | R4: Weighted Repurchases | S4: Autoattendance | T4: New 1 on 1 Students | U4: total 1 on 1 students | V4: Average AI Score for Progress Updates
A5: Aaron Schneberger | B5: Distinguished | C5: Ian Plamondon | D5: 46104 | E5: 30 | F5: 27.88 | G5: 0.9292 | H5: 38 | I5: 40.44 | J5: 1.0641 | K5: 0.2144 | L5: 1 | M5: 1 | N5: 8-Mar | O5: 0.88888889 | S5: 3 | T5: 12 | U5: 25
A6: Akeema Williams | B6: Distinguished | C6: Ian Plamondon | D6: 45519 | E6: 30 | F6: 30 | G6: 1 | H6: 38 | I6: 38 | J6: 1 | K6: 0.1782 | L6: 0.974 | M6: 1 | N6: 0/1 | O6: 0.96153846 | T6: 1 | U6: 32
A7: Alex Small | B7: Premium | C7: Ela Cross | D7: 43907 | E7: 12 | F7: 15 | G7: 1.25 | H7: 16 | I7: 18.38 | J7: 1.1484 | K7: 0.132 | L7: 1 | M7: 1 | N7: 0/0 | O7: 0.66666667 | T7: 0 | U7: 9
A8: Alexa Pinera | B8: Premium | C8: Ian Plamondon | D8: 43812 | E8: 30 | F8: 18.88 | G8: 0.6292 | H8: 30 | I8: 81.38 | J8: 2.7125 | K8: 0.0559 | L8: 1 | M8: 1 | N8: 4-Apr | O8: 0.8 | T8: 5 | U8: 17
A9: Alexandra Berrios | B9: Distinguished | C9: Kristin Haase-Alvey | D9: 45755 | E9: 12 | F9: 15.25 | G9: 1.2708 | H9: 16 | I9: 18.06 | J9: 1.1289 | K9: 0.2371 | L9: 0.979 | M9: 1 | N9: 4-Jan | O9: 1 | S9: 2 | T9: 9 | U9: 28
A10: Alexis Boucher | B10: Distinguished | C10: Ian Plamondon | D10: 43749 | E10: 30 | F10: 23.13 | G10: 0.7708 | H10: 38 | I10: 34.44 | J10: 0.9063 | K10: 0.2811 | L10: 0.882 | M10: 0.97183099 | N10: 4-Feb | O10: 0.73684211 | S10: 0 | T10: 6 | U10: 29
A11: Alison Trumbull | B11: Premium | C11: Geoff St. Marie | D11: 39309 | E11: 12 | F11: 6.5 | G11: 0.5417 | H11: 16 | I11: 17.31 | J11: 1.082 | K11: 0.3888 | L11: 0.692 | M11: 0.95238095 | N11: 0/0 | O11: 0.42857143 | S11: 1 | T11: 0 | U11: 7
A12: Allison Peck | B12: Distinguished | C12: Kristin Haase-Alvey | D12: 45223 | E12: 12 | F12: 6 | G12: 0.5 | H12: 16 | I12: 15.88 | J12: 0.9922 | K12: 0.4166 | L12: 0.944 | M12: 1 | N12: 0/1 | O12: 1 | T12: 1 | U12: 8
A13: Amber Maldonado | B13: Distinguished | C13: Annelies de Groot | D13: 45683 | E13: 30 | F13: 20.25 | G13: 0.675 | H13: 38 | I13: 33.38 | J13: 0.8783 | K13: 0.5555 | L13: 0.875 | M13: 0.91803279 | N13: 4-Apr | O13: 0.85714286 | P13: 1 | Q13: 10 | S13: 3 | T13: 12 | U13: 32
A14: Amelia Sain | B14: Premium | C14: Geoff St. Marie | D14: 43479 | E14: 30 | F14: 8.13 | G14: 0.2708 | H14: 38 | I14: 45.33 | J14: 1.193 | K14: 0.2179 | L14: 0.952 | M14: 1 | N14: 0/1 | O14: 0.3 | P14: 1 | Q14: 10 | T14: 1 | U14: 12
A15: Amy Kim | B15: Distinguished | C15: Ela Cross | D15: 46020 | E15: 30 | F15: 27.38 | G15: 0.9125 | H15: 38 | I15: 37 | J15: 0.9737 | K15: 0.0895 | L15: 0.724 | M15: 0.9537037 | N15: 0/7 | O15: 0.5 | P15: 1 | Q15: 0 | S15: 3 | T15: 13 | U15: 39
A16: Ana Heiser | B16: Distinguished | C16: Kristin Haase-Alvey | D16: 45538 | E16: 30 | F16: 17 | G16: 0.5667 | H16: 30 | I16: 37.69 | J16: 1.2563 | K16: 0.096 | L16: 0.933 | M16: 0.95238095 | N16: 5-May | O16: 1 | S16: 1 | T16: 9 | U16: 18
A17: Andres Jarquin | B17: Distinguished | C17: Ian Plamondon | D17: 45876 | E17: 30 | F17: 29.13 | G17: 0.9708 | H17: 38 | I17: 40.75 | J17: 1.0724 | K17: 0.2249 | L17: 0.923 | M17: 1 | N17: 3-Jan | O17: 0.45454545 | T17: 8 | U17: 31
A18: Andrew Brown | B18: Distinguished | C18: Ian Plamondon | D18: 44218 | E18: 30 | F18: 35 | G18: 1.1667 | H18: 38 | I18: 46.81 | J18: 1.2319 | K18: 0.129 | L18: 0.968 | M18: 0.98496241 | N18: 2-Jan | O18: 0.64 | P18: 1 | Q18: 10 | T18: 6 | U18: 36
A19: Andrew Gehlot | B19: Premium | C19: Ela Cross | D19: 42825 | E19: 30 | F19: 21.13 | G19: 0.7042 | H19: 38 | I19: 39.31 | J19: 1.0345 | K19: 0.2518 | L19: 0.864 | M19: 0.87012987 | N19: 1-Jan | O19: 0.875 | S19: 3 | T19: 3 | U19: 21
A20: Andrew League | B20: Distinguished | C20: Ian Plamondon | D20: 46065 | E20: 30 | F20: 30.5 | G20: 1.0167 | H20: 38 | I20: 40.69 | J20: 1.0707 | K20: 0.2125 | L20: 0.966 | M20: 1 | N20: 4-Feb | O20: 0.70588235 | T20: 15 | U20: 40
A21: Anna Gilbert | B21: Distinguished | C21: Kristin Haase-Alvey | D21: 45294 | E21: 12 | F21: 7.25 | G21: 0.6042 | H21: 16 | I21: 14 | J21: 0.875 | K21: 0.0357 | L21: 1 | M21: 1 | N21: 1-Jan | O21: 0.85714286 | T21: 3 | U21: 11
A22: Anna Jasko | B22: Distinguished | C22: Ela Cross | D22: 46090 | E22: 30 | F22: 30.5 | G22: 1.0167 | H22: 38 | I22: 43.44 | J22: 1.1431 | K22: 0.3303 | L22: 0.965 | M22: 0.99152542 | N22: 2-Feb | O22: 0.46153846 | T22: 10 | U22: 36
A23: Annie Sylvester | B23: Distinguished | C23: Ela Cross | D23: 46052 | E23: 35 | F23: 33.88 | G23: 0.9679 | H23: 43 | I23: 40.44 | J23: 0.9404 | K23: 0.1725 | L23: 0.845 | M23: 0.98473282 | N23: 2-Feb | O23: 0.66666667 | P23: 2 | Q23: 5 | T23: 6 | U23: 37
A24: Armand Brouty | B24: Distinguished | C24: Ian Plamondon | D24: 44015 | E24: 30 | F24: 34 | G24: 1.1333 | H24: 38 | I24: 58 | J24: 1.5263 | K24: 0.0795 | L24: 1 | M24: 0.95081967 | N24: 3-Mar | O24: 1 | P24: 2 | Q24: 10 | T24: 12 | U24: 26
A25: Ashley Scorsone | B25: Premium | C25: Geoff St. Marie | D25: 42909 | E25: 35 | F25: 35.06 | G25: 1.0018 | H25: 43 | I25: 61.94 | J25: 1.4404 | K25: 0.1153 | L25: 0.96 | M25: 0.93984962 | N25: 1-Jan | O25: 0.92 | T25: 4 | U25: 28
A26: Autumn Reed | B26: Advanced | C26: Geoff St. Marie | D26: 46003 | E26: 20 | F26: 19 | G26: 0.95 | H26: 24 | I26: 32.38 | J26: 1.349 | K26: 0.1319 | L26: 0.793 | M26: 0.98666667 | N26: 0/0 | O26: 0.47058824 | P26: 1 | Q26: 9 | T26: 1 | U26: 22
A27: Ayman Smoot | B27: Distinguished | C27: Annelies de Groot | D27: 45225 | E27: 12 | F27: 13.25 | G27: 1.1042 | H27: 16 | I27: 31.75 | J27: 1.9844 | K27: 0.3666 | L27: 1 | M27: 0.93877551 | N27: 4-Apr | O27: 0.77777778 | T27: 4 | U27: 14
A28: Ben Taylor | B28: Premium | C28: Kristin Haase-Alvey | D28: 44281 | E28: 30 | F28: 14.5 | G28: 0.4833 | H28: 30 | I28: 42.63 | J28: 1.4208 | K28: 0.0787 | L28: 1 | M28: 1 | N28: 1-Jan | O28: 1 | T28: 5 | U28: 15
A29: Blake Maly | B29: Distinguished | C29: Annelies de Groot | D29: 46042 | E29: 35 | F29: 36.63 | G29: 1.0464 | H29: 43 | I29: 40.56 | J29: 0.9433 | K29: 0.1767 | L29: 0.968 | M29: 0.99300699 | N29: 0/0 | O29: 0.89655172 | T29: 6 | U29: 46
A30: Brandon Engle | B30: Distinguished | C30: Annelies de Groot | D30: 45853 | E30: 35 | F30: 36.38 | G30: 1.0393 | H30: 43 | I30: 45 | J30: 1.0465 | K30: 0.1714 | L30: 0.947 | M30: 1 | N30: 2-Feb | O30: 0.92 | P30: 1 | Q30: 10 | T30: 13 | U30: 40
A31: Breanna Lowe | B31: Distinguished | C31: Katherine Marino | D31: 46127 | E31: 20 | F31: 0.75 | G31: 0.0375 | H31: 24 | I31: 19.75 | J31: 0.8229 | K31: 0.1666 | L31: 1 | M31: 1 | N31: 1-Jan | T31: 3 | U31: 3
A32: Brenna Hubnik | B32: Distinguished | C32: Annelies de Groot | D32: 45194 | E32: 12 | F32: 11.38 | G32: 0.9479 | H32: 16 | I32: 18.38 | J32: 1.1484 | K32: 0.2263 | L32: 1 | M32: 1 | N32: 0/0 | O32: 0.86666667 | T32: 0 | U32: 16
A33: Brian Cohen | B33: Premium | C33: Annelies de Groot | D33: 43536 | E33: 12 | F33: 11.63 | G33: 0.9688 | H33: 16 | I33: 15.13 | J33: 0.9453 | K33: 0.2349 | L33: 0.975 | M33: 1 | N33: 1-Jan | O33: 1 | T33: 1 | U33: 15
A34: Brian James | B34: Distinguished | C34: Annelies de Groot | D34: 45264 | E34: 30 | F34: 39.38 | G34: 1.3125 | H34: 38 | I34: 44.63 | J34: 1.1743 | K34: 0.0964 | L34: 0.989 | M34: 0.99319728 | N34: 2-Feb | O34: 0.82142857 | P34: 1 | Q34: 10 | S34: 1 | T34: 7 | U34: 41
A35: Brian Johnson | B35: Distinguished | C35: Kristin Haase-Alvey | D35: 46090 | E35: 30 | F35: 30.63 | G35: 1.0208 | H35: 38 | I35: 42.69 | J35: 1.1234 | K35: 0.3925 | L35: 1 | M35: 1 | N35: 6-Apr | O35: 0.91666667 | T35: 14 | U35: 34
A36: Brittany Drew | B36: Distinguished | C36: Ela Cross | D36: 46037 | E36: 30 | F36: 29.5 | G36: 0.9833 | H36: 38 | I36: 38.38 | J36: 1.0099 | K36: 0.3525 | L36: 1 | M36: 1 | N36: 3-Feb | O36: 0.89473684 | P36: 3 | Q36: 10 | T36: 12 | U36: 32
A37: Brock Dilley | B37: Distinguished | C37: Annelies de Groot | D37: 45992 | E37: 35 | F37: 41.25 | G37: 1.1786 | H37: 43 | I37: 46.44 | J37: 1.0799 | K37: 0.1702 | L37: 0.978 | M37: 1 | N37: 11-Aug | O37: 0.78947368 | P37: 2 | Q37: 7 | T37: 21 | U37: 55
A38: Bryant Salinas | B38: Premium | C38: Geoff St. Marie | D38: 43363 | E38: 30 | F38: 31 | G38: 1.0333 | H38: 38 | I38: 41.94 | J38: 1.1036 | K38: 0.2254 | L38: 0.94 | M38: 0.9380531 | N38: 2-Jan | O38: 0.96 | P38: 1 | Q38: 7 | S38: 1 | T38: 2 | U38: 33
A39: Cadence Liles | B39: Advanced | C39: Geoff St. Marie | D39: 46097 | E39: 20 | F39: 16.5 | G39: 0.825 | H39: 24 | I39: 26.38 | J39: 1.099 | K39: 0.2032 | L39: 0.838 | M39: 0.98333333 | N39: 5-May | O39: 0.57142857 | P39: 3 | Q39: 10 | S39: 4 | T39: 6 | U39: 15
A40: Cait White | B40: Premium | C40: Ela Cross | D40: 43903 | E40: 12 | F40: 7.56 | G40: 0.6302 | H40: 16 | I40: 16.13 | J40: 1.0078 | L40: 1 | M40: 1 | N40: 0/0 | O40: 0.83333333 | T40: 0 | U40: 7
...

Sheet MasterTutor
A1: Full Name | B1: Faculty Leader | C1: Professional/Adjunct | D1: Tier
A2: Denise Jefferson | B2: Ela Cross | C2: Adjunct | D2: Distinguished
A3: Kayleigh Puliafico | B3: Ela Cross | C3: Adjunct | D3: Distinguished
A4: Nisha Fletcher | B4: Kristin Haase-Alvey | C4: Adjunct | D4: Distinguished
A5: Jackson Weier | B5: Geoff St. Marie | C5: Adjunct | D5: Distinguished
A6: Gene Costa | B6: Ela Cross | C6: Professional | D6: Distinguished
A7: Vincent Cross | B7: Kristin Haase-Alvey | C7: Professional | D7: Distinguished
A8: Kate Haldeman | B8: Geoff St. Marie | C8: Professional | D8: Advanced
A9: Justin Hill | B9: Kristin Haase-Alvey | C9: Professional | D9: Distinguished
A10: Tim Page | B10: Annelies de Groot | C10: Professional | D10: Advanced
A11: Judi Abo Hana | B11: Geoff St. Marie | C11: Adjunct | D11: Advanced
A12: Lisa Bartle | B12: Annelies de Groot | C12: Adjunct | D12: Premium
... A220: Madia Banda | B220: Geoff St. Marie | C220: Professional | D220: Advanced
