Workbook

Sheet MonthlyMetric
A1: Tutor Name | B1: Date Range | C1: % to Delivery Target | D1: % to Availability Target | E1: % Sessions on Time | F1: % Parents Updates Done on Time | G1: % of Active Students with Progress Updates Completed in last 2 months | H1: Weighted Repurchases | I1: OLD PPW | J1: Ratio of PPW Events with Attached PPWs | K1: Tier | L1: Adjunct/Professional | M1: Faculty Leader
A2: Aaron Schneberger | B2: 10/5/25 - 11/1/25 | C2: 1.2813 | D2: 1.1602 | E2: 1 | F2: 1 | G2: 0.90909091 | H2: 3 | I2: 2/4 | J2: 0.5 | K2: =VLOOKUP(A2,MasterTutor!A:D,4,FALSE) -> #N/A | L2: =VLOOKUP(A2,MasterTutor!A:D,3,FALSE) -> #N/A | M2: =VLOOKUP(A2,MasterTutor!A:D,2,FALSE) -> #N/A
A3: Aaron Schneberger | B3: 11/2/25 - 11/29/25 | C3: 0.76 | D3: 0.78 | E3: 1 | F3: 1 | G3: 0.91 | H3: 1 | K3: =VLOOKUP(A3,MasterTutor!A:D,4,FALSE) -> #N/A | L3: =VLOOKUP(A3,MasterTutor!A:D,3,FALSE) -> #N/A | M3: =VLOOKUP(A3,MasterTutor!A:D,2,FALSE) -> #N/A
A4: Aaron Schneberger | B4: 5/18/25 - 6/14/25 | C4: 0.74 | D4: 0.9 | E4: 0.99 | F4: 1 | G4: 1 | H4: 10 | I4: 1 | J4: =I4 -> 1 | K4: =VLOOKUP(A4,MasterTutor!A:D,4,FALSE) -> #N/A | L4: =VLOOKUP(A4,MasterTutor!A:D,3,FALSE) -> #N/A | M4: =VLOOKUP(A4,MasterTutor!A:D,2,FALSE) -> #N/A
A5: Aaron Schneberger | B5: 6/15/25 - 7/12/25 | C5: 0.5 | D5: 0.81 | E5: 1 | F5: 0.93 | G5: 0.7 | H5: 2 | I5: 2/3 | J5: 0.67 | K5: =VLOOKUP(A5,MasterTutor!A:D,4,FALSE) -> #N/A | L5: =VLOOKUP(A5,MasterTutor!A:D,3,FALSE) -> #N/A | M5: =VLOOKUP(A5,MasterTutor!A:D,2,FALSE) -> #N/A
A6: Aaron Schneberger | B6: 7/13/25 - 8/10/25 | C6: 0.48 | D6: 0.5 | E6: 1 | F6: 1 | G6: 0.71 | H6: 3 | I6: 1 | J6: =I6 -> 1 | K6: =VLOOKUP(A6,MasterTutor!A:D,4,FALSE) -> #N/A | L6: =VLOOKUP(A6,MasterTutor!A:D,3,FALSE) -> #N/A | M6: =VLOOKUP(A6,MasterTutor!A:D,2,FALSE) -> #N/A
A7: Aaron Schneberger | B7: 8/10/25 - 9/6/25 | C7: 1.2 | D7: 1.24 | E7: 1 | F7: 1 | G7: 1 | H7: 4 | K7: =VLOOKUP(A7,MasterTutor!A:D,4,FALSE) -> #N/A | L7: =VLOOKUP(A7,MasterTutor!A:D,3,FALSE) -> #N/A | M7: =VLOOKUP(A7,MasterTutor!A:D,2,FALSE) -> #N/A
A8: Aaron Schneberger | B8: 9/7/25 - 10/4/25 | C8: 1.06 | D8: 1.1 | E8: 1 | F8: 0.97 | G8: 0.82 | H8: 6 | I8: 1/1 | J8: 1 | K8: =VLOOKUP(A8,MasterTutor!A:D,4,FALSE) -> #N/A | L8: =VLOOKUP(A8,MasterTutor!A:D,3,FALSE) -> #N/A | M8: =VLOOKUP(A8,MasterTutor!A:D,2,FALSE) -> #N/A
A9: Akeema Williams | B9: 10/5/25 - 11/1/25 | C9: 1.0917 | D9: 1.1118 | E9: 0.99259259 | F9: 0.97916667 | G9: 0.96153846 | H9: 14 | I9: 6/10 | J9: 0.6 | K9: =VLOOKUP(A9,MasterTutor!A:D,4,FALSE) -> Advanced | L9: =VLOOKUP(A9,MasterTutor!A:D,3,FALSE) -> Professional | M9: =VLOOKUP(A9,MasterTutor!A:D,2,FALSE) -> Ian Plamondon
A10: Akeema Williams | B10: 11/2/25 - 11/29/25 | C10: 0.93 | D10: 0.96 | E10: 0.99 | F10: 0.97 | G10: 0.76 | H10: 11 | I10: 45664 | J10: 0.0014285714 | K10: =VLOOKUP(A10,MasterTutor!A:D,4,FALSE) -> Advanced | L10: =VLOOKUP(A10,MasterTutor!A:D,3,FALSE) -> Professional | M10: =VLOOKUP(A10,MasterTutor!A:D,2,FALSE) -> Ian Plamondon
A11: Akeema Williams | B11: 5/18/25 - 6/14/25 | C11: 0.75 | D11: 1.01 | E11: 1 | F11: 1 | G11: 0.9 | H11: 2 | I11: 1/2 | J11: 0.5 | K11: =VLOOKUP(A11,MasterTutor!A:D,4,FALSE) -> Advanced | L11: =VLOOKUP(A11,MasterTutor!A:D,3,FALSE) -> Professional | M11: =VLOOKUP(A11,MasterTutor!A:D,2,FALSE) -> Ian Plamondon
A12: Akeema Williams | B12: 6/15/25 - 7/12/25 | C12: 0.62 | D12: 0.92 | E12: 1 | F12: 0.77 | G12: 0.64 | H12: 2 | I12: 0 | J12: =I12 -> 0 | K12: =VLOOKUP(A12,MasterTutor!A:D,4,FALSE) -> Advanced | L12: =VLOOKUP(A12,MasterTutor!A:D,3,FALSE) -> Professional | M12: =VLOOKUP(A12,MasterTutor!A:D,2,FALSE) -> Ian Plamondon
A13: Akeema Williams | B13: 7/13/25 - 8/10/25 | C13: 0.94 | D13: 0.98 | E13: 0.99 | F13: 1 | G13: 0.46 | H13: 6 | I13: 2/3 | J13: 0.67 | K13: =VLOOKUP(A13,MasterTutor!A:D,4,FALSE) -> Advanced | L13: =VLOOKUP(A13,MasterTutor!A:D,3,FALSE) -> Professional | M13: =VLOOKUP(A13,MasterTutor!A:D,2,FALSE) -> Ian Plamondon
A14: Akeema Williams | B14: 8/10/25 - 9/6/25 | C14: 0.8 | D14: 0.97 | E14: 1 | F14: 0.99 | G14: 0.91 | H14: 10 | I14: 1/3 | J14: 0.33 | K14: =VLOOKUP(A14,MasterTutor!A:D,4,FALSE) -> Advanced | L14: =VLOOKUP(A14,MasterTutor!A:D,3,FALSE) -> Professional | M14: =VLOOKUP(A14,MasterTutor!A:D,2,FALSE) -> Ian Plamondon
A15: Akeema Williams | B15: 9/7/25 - 10/4/25 | C15: 0.96 | D15: 1.01 | E15: 0.99 | F15: 0.97 | G15: 0.74 | H15: 13 | I15: 4/6 | J15: 0.67 | K15: =VLOOKUP(A15,MasterTutor!A:D,4,FALSE) -> Advanced | L15: =VLOOKUP(A15,MasterTutor!A:D,3,FALSE) -> Professional | M15: =VLOOKUP(A15,MasterTutor!A:D,2,FALSE) -> Ian Plamondon
A16: Akeema Williams | B16: 11/30/25 - 12/27/25 | C16: 0.98 | D16: 0.98 | E16: 1 | F16: 0.95 | G16: 0.9 | H16: 19 | K16: =VLOOKUP(A16,MasterTutor!A:D,4,FALSE) -> Advanced | L16: =VLOOKUP(A16,MasterTutor!A:D,3,FALSE) -> Professional | M16: =VLOOKUP(A16,MasterTutor!A:D,2,FALSE) -> Ian Plamondon
A17: Alex Small | B17: 10/5/25 - 11/1/25 | C17: 0.9688 | D17: 1.5156 | E17: 1 | F17: 1 | G17: 0.5 | H17: 3 | I17: 1/1 | J17: 1 | K17: =VLOOKUP(A17,MasterTutor!A:D,4,FALSE) -> Premium | L17: =VLOOKUP(A17,MasterTutor!A:D,3,FALSE) -> Adjunct | M17: =VLOOKUP(A17,MasterTutor!A:D,2,FALSE) -> Ela Cross
A18: Alex Small | B18: 11/2/25 - 11/29/25 | C18: 0.8 | D18: 1.54 | E18: 1 | F18: 0.9 | G18: 0.88 | H18: 2 | K18: =VLOOKUP(A18,MasterTutor!A:D,4,FALSE) -> Premium | L18: =VLOOKUP(A18,MasterTutor!A:D,3,FALSE) -> Adjunct | M18: =VLOOKUP(A18,MasterTutor!A:D,2,FALSE) -> Ela Cross
A19: Alex Small | B19: 5/18/25 - 6/14/25 | C19: 0.31 | D19: 1 | E19: 1 | F19: 0.6 | G19: #N/A | H19: 1 | K19: =VLOOKUP(A19,MasterTutor!A:D,4,FALSE) -> Premium | L19: =VLOOKUP(A19,MasterTutor!A:D,3,FALSE) -> Adjunct | M19: =VLOOKUP(A19,MasterTutor!A:D,2,FALSE) -> Ela Cross
A20: Alex Small | B20: 6/15/25 - 7/12/25 | C20: 0 | D20: 0.79 | E20: 0 | F20: 0 | G20: 0 | H20: #N/A | K20: =VLOOKUP(A20,MasterTutor!A:D,4,FALSE) -> Premium | L20: =VLOOKUP(A20,MasterTutor!A:D,3,FALSE) -> Adjunct | M20: =VLOOKUP(A20,MasterTutor!A:D,2,FALSE) -> Ela Cross
A21: Alex Small | B21: 7/13/25 - 8/10/25 | C21: 0 | D21: 1 | E21: 0 | F21: 0 | G21: 0 | H21: #N/A | K21: =VLOOKUP(A21,MasterTutor!A:D,4,FALSE) -> Premium | L21: =VLOOKUP(A21,MasterTutor!A:D,3,FALSE) -> Adjunct | M21: =VLOOKUP(A21,MasterTutor!A:D,2,FALSE) -> Ela Cross
A22: Alex Small | B22: 8/10/25 - 9/6/25 | C22: 0.76 | D22: 1.42 | E22: 1 | F22: 1 | G22: 0 | H22: 2 | I22: 3/5 | J22: 0.6 | K22: =VLOOKUP(A22,MasterTutor!A:D,4,FALSE) -> Premium | L22: =VLOOKUP(A22,MasterTutor!A:D,3,FALSE) -> Adjunct | M22: =VLOOKUP(A22,MasterTutor!A:D,2,FALSE) -> Ela Cross
A23: Alex Small | B23: 9/7/25 - 10/4/25 | C23: 1.14 | D23: 1.46 | E23: 1 | F23: 0.73 | G23: 0 | H23: 3 | K23: =VLOOKUP(A23,MasterTutor!A:D,4,FALSE) -> Premium | L23: =VLOOKUP(A23,MasterTutor!A:D,3,FALSE) -> Adjunct | M23: =VLOOKUP(A23,MasterTutor!A:D,2,FALSE) -> Ela Cross
A24: Alex Small | B24: 11/30/25 - 12/27/25 | C24: 0.35 | D24: 1.4 | E24: 1 | F24: 0.91 | G24: 0.67 | H24: 0 | K24: =VLOOKUP(A24,MasterTutor!A:D,4,FALSE) -> Premium | L24: =VLOOKUP(A24,MasterTutor!A:D,3,FALSE) -> Adjunct | M24: =VLOOKUP(A24,MasterTutor!A:D,2,FALSE) -> Ela Cross
A25: Alexa Pinera | B25: 10/5/25 - 11/1/25 | C25: 0.6257 | D25: 2.2516 | E25: 0.94029851 | F25: 0.97619048 | G25: 0.75 | H25: 1 | I25: 4/4 | J25: 1 | K25: =VLOOKUP(A25,MasterTutor!A:D,4,FALSE) -> Premium | L25: =VLOOKUP(A25,MasterTutor!A:D,3,FALSE) -> Professional | M25: =VLOOKUP(A25,MasterTutor!A:D,2,FALSE) -> Ian Plamondon
A26: Alexa Pinera | B26: 11/2/25 - 11/29/25 | C26: 0.7 | D26: 1.99 | E26: 0.97 | F26: 1 | G26: 0.71 | H26: 5 | I26: 45691 | J26: 0.0066666667 | K26: =VLOOKUP(A26,MasterTutor!A:D,4,FALSE) -> Premium | L26: =VLOOKUP(A26,MasterTutor!A:D,3,FALSE) -> Professional | M26: =VLOOKUP(A26,MasterTutor!A:D,2,FALSE) -> Ian Plamondon
A27: Alexa Pinera | B27: 5/18/25 - 6/14/25 | C27: 0.96 | D27: 1.65 | E27: 0.97 | F27: 1 | G27: 0.9 | H27: 0 | I27: 3/4 | J27: 0.75 | K27: =VLOOKUP(A27,MasterTutor!A:D,4,FALSE) -> Premium | L27: =VLOOKUP(A27,MasterTutor!A:D,3,FALSE) -> Professional | M27: =VLOOKUP(A27,MasterTutor!A:D,2,FALSE) -> Ian Plamondon
A28: Alexa Pinera | B28: 6/15/25 - 7/12/25 | C28: 0.52 | D28: 1.83 | E28: 0.99 | F28: 1 | G28: 0.77 | H28: 2 | I28: 1 | J28: =I28 -> 1 | K28: =VLOOKUP(A28,MasterTutor!A:D,4,FALSE) -> Premium | L28: =VLOOKUP(A28,MasterTutor!A:D,3,FALSE) -> Professional | M28: =VLOOKUP(A28,MasterTutor!A:D,2,FALSE) -> Ian Plamondon
A29: Alexa Pinera | B29: 7/13/25 - 8/10/25 | C29: 0.82 | D29: 1.92 | E29: 0.96 | F29: 1 | G29: 0.56 | H29: 2 | I29: 1 | J29: =I29 -> 1 | K29: =VLOOKUP(A29,MasterTutor!A:D,4,FALSE) -> Premium | L29: =VLOOKUP(A29,MasterTutor!A:D,3,FALSE) -> Professional | M29: =VLOOKUP(A29,MasterTutor!A:D,2,FALSE) -> Ian Plamondon
A30: Alexa Pinera | B30: 8/10/25 - 9/6/25 | C30: 0.8 | D30: 1.03 | E30: 0.99 | F30: 1 | G30: 0.88 | H30: 1 | I30: 0/1 | J30: 0 | K30: =VLOOKUP(A30,MasterTutor!A:D,4,FALSE) -> Premium | L30: =VLOOKUP(A30,MasterTutor!A:D,3,FALSE) -> Professional | M30: =VLOOKUP(A30,MasterTutor!A:D,2,FALSE) -> Ian Plamondon
A31: Alexa Pinera | B31: 9/7/25 - 10/4/25 | C31: 0.75 | D31: 2.19 | E31: 0.94 | F31: 1 | G31: 0.93 | H31: 0 | I31: 3/3 | J31: 1 | K31: =VLOOKUP(A31,MasterTutor!A:D,4,FALSE) -> Premium | L31: =VLOOKUP(A31,MasterTutor!A:D,3,FALSE) -> Professional | M31: =VLOOKUP(A31,MasterTutor!A:D,2,FALSE) -> Ian Plamondon
A32: Alexa Pinera | B32: 11/30/25 - 12/27/25 | C32: 0.6 | D32: 1.82 | E32: 1 | F32: 0.98 | G32: 0.81 | H32: 4 | I32: 1 | J32: 1 | K32: =VLOOKUP(A32,MasterTutor!A:D,4,FALSE) -> Premium | L32: =VLOOKUP(A32,MasterTutor!A:D,3,FALSE) -> Professional | M32: =VLOOKUP(A32,MasterTutor!A:D,2,FALSE) -> Ian Plamondon
A33: Alexandra Berrios | B33: 10/5/25 - 11/1/25 | C33: 1.7344 | D33: 1.3555 | E33: 0.98888889 | F33: 0.78125 | G33: 0.70588235 | H33: 7 | I33: 2/3 | J33: 0.66 | K33: =VLOOKUP(A33,MasterTutor!A:D,4,FALSE) -> Advanced | L33: =VLOOKUP(A33,MasterTutor!A:D,3,FALSE) -> Adjunct | M33: =VLOOKUP(A33,MasterTutor!A:D,2,FALSE) -> Kristin Haase-Alvey
A34: Alexandra Berrios | B34: 10/5/25 - 11/1/25 | C34: 1.7344 | D34: 1.3555 | E34: 0.98888889 | F34: 0.78125 | G34: 0.70588235 | H34: 7 | I34: 2/3 | J34: =_xlfn.TEXTBEFORE(I34, "/")/_xlfn.TEXTAFTER(I34,"/") -> 0.66666667 | K34: =VLOOKUP(A34,MasterTutor!A:D,4,FALSE) -> Advanced | L34: =VLOOKUP(A34,MasterTutor!A:D,3,FALSE) -> Adjunct | M34: =VLOOKUP(A34,MasterTutor!A:D,2,FALSE) -> Kristin Haase-Alvey
A35: Alexandra Berrios | B35: 11/2/25 - 11/29/25 | C35: 1.67 | D35: 1.38 | E35: 1 | F35: 0.47 | G35: 0.81 | H35: 11 | I35: 0/5 | J35: 0 | K35: =VLOOKUP(A35,MasterTutor!A:D,4,FALSE) -> Advanced | L35: =VLOOKUP(A35,MasterTutor!A:D,3,FALSE) -> Adjunct | M35: =VLOOKUP(A35,MasterTutor!A:D,2,FALSE) -> Kristin Haase-Alvey
A36: Alexandra Berrios | B36: 5/18/25 - 6/14/25 | C36: 0.54 | D36: 0.97 | E36: 1 | F36: 0.85 | G36: 1 | H36: 1 | K36: =VLOOKUP(A36,MasterTutor!A:D,4,FALSE) -> Advanced | L36: =VLOOKUP(A36,MasterTutor!A:D,3,FALSE) -> Adjunct | M36: =VLOOKUP(A36,MasterTutor!A:D,2,FALSE) -> Kristin Haase-Alvey
A37: Alexandra Berrios | B37: 6/15/25 - 7/12/25 | C37: 0.02 | D37: 0.63 | E37: 1 | F37: 1 | G37: 1 | H37: #N/A | K37: =VLOOKUP(A37,MasterTutor!A:D,4,FALSE) -> Advanced | L37: =VLOOKUP(A37,MasterTutor!A:D,3,FALSE) -> Adjunct | M37: =VLOOKUP(A37,MasterTutor!A:D,2,FALSE) -> Kristin Haase-Alvey
A38: Alexandra Berrios | B38: 7/13/25 - 8/10/25 | C38: 0.8 | D38: 1.29 | E38: 1 | F38: 0.87 | G38: 0.8 | H38: #N/A | I38: 1 | J38: =I38 -> 1 | K38: =VLOOKUP(A38,MasterTutor!A:D,4,FALSE) -> Advanced | L38: =VLOOKUP(A38,MasterTutor!A:D,3,FALSE) -> Adjunct | M38: =VLOOKUP(A38,MasterTutor!A:D,2,FALSE) -> Kristin Haase-Alvey
A39: Alexandra Berrios | B39: 8/10/25 - 9/6/25 | C39: 1.02 | D39: 1.48 | E39: 1 | F39: 0.95 | G39: 0.4 | H39: 2 | K39: =VLOOKUP(A39,MasterTutor!A:D,4,FALSE) -> Advanced | L39: =VLOOKUP(A39,MasterTutor!A:D,3,FALSE) -> Adjunct | M39: =VLOOKUP(A39,MasterTutor!A:D,2,FALSE) -> Kristin Haase-Alvey
A40: Alexandra Berrios | B40: 9/7/25 - 10/4/25 | C40: 1.85 | D40: 1.65 | E40: 1 | F40: 0.75 | G40: 0.58 | H40: 8 | I40: 5/6 | J40: 0.83 | K40: =VLOOKUP(A40,MasterTutor!A:D,4,FALSE) -> Advanced | L40: =VLOOKUP(A40,MasterTutor!A:D,3,FALSE) -> Adjunct | M40: =VLOOKUP(A40,MasterTutor!A:D,2,FALSE) -> Kristin Haase-Alvey
...

Sheet ProgressUpdateEmails
A1: update_id | B1: sent_at | C1: tutor | D1: team | E1: course_id | F1: student_name | G1: body | H1: AI Score
A2: 10918864 | B2: 45991 | C2: Christine Santos | D2: Team Cross | E2: 85148 | F2: Lev Wechselblatt | G2: Hi Daniella, I hope youâ€™re doing well! I wanted to share an update on Levâ€™s recent progress as he prepares for the ACT. During our last session, Lev and I reviewed the questions he missed from his recent practice test. Iâ€™m happy to report that he showed considerable improvement in the â€œstudent as editorâ€ questionsâ€”an area weâ€™ve been focusing on, and itâ€™s wonderful to see that our hard work is paying off. Levâ€™s continued progress in this area will serve him well on the actual test. We also identified several more questions, particularly in the science section and the English sectionâ€™s punctuation items, that Lev can easily capture for additional points. To support this, my recommendation is that we begin incorporating more mixed review, focusing on strategies for different science passages and targeted practice with punctuation rules in the English section. Weâ€™ll also be building in timing limits during our practice sessions to help Lev balance his time effectively and minimize rushing or simple mistakes. Despite a few missed questions, Lev performed very well on this last practice test, and Iâ€™m confident that he has all the skills needed to succeed on test dayâ€”itâ€™s just a matter of bringing everything together. If you have any questions or would like to discuss Levâ€™s progress further, please feel free to reach out by email or text. Iâ€™m always happy to help! Thank you, and I look forward to continuing to support Lev! Christine S. christine.santos@revolutionprep.com +19415649546 | H2: 3
A3: 10918868 | B3: 45991 | C3: Kristen Luigart | D3: Team Plamondon | E3: 89581 | F3: Yasmine Hammami | G3: Good evening Kirsten, First off, it was lovely to meet Yasmine this week, she's such a passionate and vibrant young lady, and I wanted to say that she was an absolute pleasure to work with! Yasmine approached the whole essay editing process with maturity and impressive self-awareness. We started this week's session by reading through all of Yasmineâ€™s PIQs, and I provided in-text comments on each. However, we ended up spending majority of our time focusing on the PIQ about her NYT program experience and her personal connection to communication, journalism, and journalistic integrity. When we began, this PIQ had strong ideas but lacked direction and clarity. The opening framed her identity as a â€œglobal writerâ€ and referenced AP English, Mock Trial, and her New York Times coursework equallyâ€”accomplishments that are truly impressive, but in the original draft appeared more as a list than a cohesive, compelling story. The essay needed specificity, stronger organization, and more â€œshow, donâ€™t tell.â€ Together, we reshaped the PIQ into a much more focused and powerful narrative. Yasmine now shares a concrete story about her personal passion for using journalism and communication to correct biased media coverage of Tunisia and the world. This shift allowed her to highlight meaningful experiences and connect them directly to her academic and professional goals. The revised essay includes vivid, authentic detailsâ€”such as using PeopleFinder, interviewing techniques, and NYT archival researchâ€”that demonstrate her initiative, curiosity, and early commitment to journalistic integrity. The new structure paints a clear picture of the work she has done and shows readers exactly why her passion is real and hard-earned. Yasmine made excellent progress in just one session, and I believe continuing to refine any college essays with consistent guidance will only make her applications stronger. I recommend meeting once weekly for one hour as needed to support any additional revisions or new essays she may need to complete for her last few applications. If youâ€™d like to discuss Yasmineâ€™s work or next steps, Iâ€™d be happy to schedule a Zoom or phone call at your convenience. Happy Thanksgiving!Â Kristen Luigart, M.Ed., M.A. kristen.luigart@revolutionprep.com +13018205071 | H3: 4
A4: 10918889 | B4: 45991 | C4: Kristen Luigart | D4: Team Plamondon | E4: 83525 | F4: Loui Takahashi | G4: Good Morning Ippei, I'm writing to give you a bit of a wrap up of all the work Loui and I have done in her tutoring sessions so far. Loui's been working extremely hard (especially with all she has going on in school and out), and her ambitious and passionate nature reflects in her writing and intelligence. Together, we have now completed Loui's personal essay, as well as her supplemental essays for Yale, the University of Vermont, Tufts, and -- most recently -- UC Berkeley, which we just finalized with only a little time to spare. Despite the tight timeline, her Berkeley essays turned out excellent. Loui's writing has a strong, innate, sense of storytelling, and a compelling voice to begin with, so working with her on her essays has really been about giving more immediacy and vibrancy to the works. (And sometimes helping her find the motivation to be passionate about some truly awful prompts! ;3) Throughout all the essays, we have focused on strengthening Loui's language and composition to create more compelling narrative flow, express more passion, and illustrate with greater clarity. The key to a good college application essay is being able to use only a couple hundred words to become a fully-fleshed out being to the numbed essay readers at university admissions. With hundreds of thousands of students applying to schools every year, essay readers tend to zone out quickly when essays are repetitive or rote. (I have personal experience with this from being the chair of admissions for UVA's honors dorm, Brown College, which had its own rigorous application essay process.) Therefore, to break through the monotonous repetition of the usual accomplishment lists draped in prose disguised as essays, a student must not only answer their prompts intelligently -- but compellingly, in order to rise above the simple 'fulfilled requirement' stack. I am confident that the essays Loui has brought from this program have all had that spark, and that they use it effectively to highlight how impressive and multifaceted Loui is as an applicant. A good example of this editing process can be seen in how, when we first reviewed Loui's Berkeley drafts, she and I both found them to come across as flat and lacking passion. The prompt, itself, was relatively dry, and without finding a way to feel passionate about the subject, Loui's work came out as simply informative and somewhat distanced. The essays read more like reports than personal reflections. Over several rounds of revision, Loui transformed them all into essays that are far more authentic, vital, and emotionally grounded. For example, the new essay on social mediaâ€™s impact on Loui's life, and her subsequent rejection of it, presents compelling statisticsâ€”such as 5.3 billion selfies are taken per day â€” that highlight Loui's wisdom in learning how to "put down the light-up brick". These striking facts, and the additional comments on the human history of appearance, helped anchor Loui's narrative in something both memorable and meaningful. With Berkeley completed, our next priority is Johns Hopkins. Brainstorming for its essays is Loui's homework for our next session on December 13. After that, we will continue on with her essays for Bowdoin, CMU, and the University of Chicago. To ensure Loui stays comfortably ahead of all deadlines, and maintains her strong momentum, I recommend meeting at least once a week for an hour until all remaining essays are completed. (Ideally, therefore, they will be finished well before their due dates). If youâ€™d like to discuss Louiâ€™s progress or upcoming plans, I would be happy to schedule a Zoom or phone call at your convenience. Warm regards, and Happy Thanksgiving! Kristen Luigart, M.Ed., M.A. Kristen.Luigart@Revolutionprep.com (301)*20-5071 | H4: 4
A5: 10918896 | B5: 45991 | C5: Myles Oldroyd | D5: Team Plamondon | E5: 90236 | F5: Brooks Main | G5: Dear Clayton, Itâ€™s been great working with you and Brooks over the past two months. As we prepare for Brooks's upcoming December SAT, I wanted to share some updates and information about what to expect. I have seen significant improvements in Brooks's two passage reading, measures of central tendency, main ideas, and interpreting equations. They have shown consistent progress in homework and practice tests. This consistent improvement has been evident in a new high score on a practice test of 1440. For this exam, our goal is 1500. While we cannot guarantee a specific score, we have worked diligently towards this goal through B-PRIMES, Title 10, and IESME. It's important to consider the impact of the test zone on Brooks's performance. Ensuring a good night's sleep throughout the week leading up to the test is crucial, as just the night before isn't enough. We have also discussed strategies to manage test anxiety, which can impact scores. I am looking forward to continuing to work with Brooks after the test so that we can work towards further improvements on the SAT. I recommend maintaining at least one session a week until Brooks is happy with his score in order to help them achieve their goals. Please let me know if you have any questions or if there are any adjustments you would like to make to our plan. Iâ€™m also able to schedule a time to talk by phone if that would be helpful. I am happy to support Brooks in their continued academic journey. Thank you and stay safe, Myles O. myles.oldroyd@revolutionprep.com +15304434701 | H5: 3
A6: 10918902 | B6: 45991 | C6: Myles Oldroyd | D6: Team Plamondon | E6: 83644 | F6: Reese Migdal | G6: Dear Kristina, I hope youâ€™re doing well. I wanted to share an update on Reeseâ€™s progress over the past two months and outline our plan moving forward. Over the last two months, Reese has shown meaningful improvement in command of textual evidence, central ideas and details, and trigonometric identities.While working on precalc, Reese seemed to grasp how to view trigonometric identities as a puzzle to solve rather than an annoyance to complete. Our goals over the next phase of instruction include continuing to build his SAT readiness, deepening mastery of reading skills, and ensuring Reese feels confident applying these skills independently. To support this, I recommend regular sessions of at least once a week to prepare for the SAT and keep up with his math course. In the coming sessions, I plan to focus on the reading portion of the SAT including reading comprehension and data analysis, while continuing to reinforce previous learning targets. If you have any questions or if there are adjustments youâ€™d like to make to our plan, please feel free to reach out. Iâ€™m happy to schedule a call if that would be helpful. Thank you for your continued partnership. Itâ€™s a pleasure working with Reese and supporting his academic growth. Thank you and stay safe, Myles O. myles.oldroyd@revolutionprep.com +15304434701 | H6: 3
A7: 10918905 | B7: 45991 | C7: Tea Stewart | D7: Team Haase-Alvey | E7: 81932 | F7: Oscar Anguiano | G7: Hi Oscar, I hope you are having a great fall season. Itâ€™s been wonderful working with you and Oscar over the past couple of months. I wanted to take a moment to share some of the progress weâ€™ve made so far and outline my thoughts moving forward. I have seen significant improvements in Oscarâ€™s understanding and application of graph transformations, particularly with horizontal shifts. Over the semester, he has become much more confident identifying when a function is moving left or right and applying that knowledge accurately in practice problems. In addition, Oscar has shown strong growth in his work with similar triangle ratios. He consistently sets up correct proportions and demonstrates a solid understanding of how corresponding sides relate, which has been a highlight of his progress. His willingness to ask questions and revisit challenging problems has been one of the biggest contributors to this growth, and Iâ€™ve seen his confidence increase as a result. Our current short-term goals for Oscar include strengthening his understanding of function notation, learning to distinguish between stretches and compressions, and accurately identifying reflections across the x- and y-axis. In geometry, short-term goals also include improving his ability to solve proportions that lead to quadratic equations and deepening his understanding of geometric means within triangle relationships. The overall goal remains building Oscarâ€™s confidence and mastery in algebra and geometry so he feels prepared and capable in his math coursework. Based on Oscarâ€™s progress, I suggest we continue with our weekly 60-minute sessions moving forward. Overall, Oscar has worked hard throughout the semester, and his progress and grades reflects that effort. I look forward to continuing to support his growth in these areas. Please feel free to reach out if you have any questions or would like additional updates. Tea S. tea.stewart@revolutionprep.com +17193017642 | H7: 3
A8: 10918906 | B8: 45991 | C8: Tea Stewart | D8: Team Haase-Alvey | E8: 78245 | F8: Noor El-Helw | G8: Hi Dania, I hope you are having a great fall season. Itâ€™s been wonderful working with you and Noor over the past couple of months. I wanted to take a moment to share some of the progress weâ€™ve made so far and outline my thoughts moving forward. I have seen significant improvements in Noorâ€™s understanding and setup of improper integrals. She has consistently demonstrated the ability to recognize when an integral requires limits or a domain adjustment, and her accuracy in forming the correct limit expressions has strengthened throughout the semester. Noor has also done well with tangent line equations for parametric functions, showing confidence in applying derivatives correctly to construct linear approximations. Additionally, she has shown strong mastery in working with speed and velocity vectors of parametric functions, as well as selecting appropriate radian values to construct polar coordinate tables. In integration, Noor has done excellent work eliminating factors to determine unknown constants for partial fractions, a skill that has noticeably improved her efficiency and accuracy. Noor continues to work on several more advanced skills appropriate for Calculus BC. We will focus on strengthening her ability to determine when an improper integral converges or diverges, as well as developing clearer instincts on when extended Lâ€™HÃ´pitalâ€™s Rule is appropriate. She will also benefit from more targeted practice finding vertical and horizontal tangent lines for parametric curves. In polar coordinates, Noorâ€™s next steps include improving her graphing of polar functions with negative r-values and building confidence in interpreting their directional behavior. For integration, she will continue to work on simplifying improper rational expressions before applying partial fractions. We will also devote additional time to solving for t in complex trigonometric equations, an area that will benefit from repeated structured practice. Our current short-term goals for Noor include strengthening her convergence/divergence reasoning, mastering tangent line behavior in parametric curves, and improving clarity with both polar graphing techniques and trigonometric equation solving. The overall goal remains to build Noorâ€™s confidence and mastery across all BC topics so she feels fully prepared for assessments and the AP Exam. Based on Noorâ€™s progress, I recommend maintaining our current schedule of two 60-minute sessions to support steady development as we move into more challenging units. Noor has shown consistent effort throughout the semester, and her progress reflects that dedication. I look forward to continuing to support her growth in these areas. Please feel free to reach out if you have any questions or would like additional updates. Tea S. tea.stewart@revolutionprep.com +17193017642 | H8: 4
A9: 10918907 | B9: 45991 | C9: Tea Stewart | D9: Team Haase-Alvey | E9: 91642 | F9: Gavin Gardner | G9: Hi Shanna, I hope you are having a great fall season. Itâ€™s been wonderful working with you and Gavin over the past couple of months. I wanted to take a moment to share some of the progress weâ€™ve made so far and outline my thoughts moving forward. I have seen improvements in Gavinâ€™s ability to solve systems of equations. He has become more confident setting up equations, choosing appropriate methods, and checking his work for accuracy. Gavin has also done well using the Desmos linear regression formula to analyze linear relationships and interpret results correctly, which has strengthened his problem-solving skills in algebra. In English, he has shown strong progress identifying introductory phrases, demonstrating a clearer understanding of sentence structure and grammatical components. Moving forward, Gavin will continue working on several key areas. In math, he will benefit from becoming more comfortable with the functions and tools embedded within Desmos, which will help him work more efficiently and accurately during assignments. In writing, he will continue developing his ability to combine two complete sentences using the three correct methodsâ€”comma + coordinating conjunction, semicolon, or a period. Improving consistency with these skills will support his clarity and correctness in written communication. Additionally, we will focus on building stronger habits around homework completion, especially avoiding last-minute work so he can focus on quality and comprehension. Our current short-term goals for Gavin include strengthening his command of the three ways to combine complete sentences, improving his use of Desmos tools, and establishing consistent homework routines. The overall goal remains building Gavinâ€™s confidence, accuracy, and independence across his math and writing tasks. Based on Gavinâ€™s progress, I recommend we maintain our current schedule of weekly 60-minute sessions to support steady growth while continuing to reinforce foundational skills. I look forward to continuing to support his growth in these areas. Please feel free to reach out if you have any questions or would like additional updates. Tea S. tea.stewart@revolutionprep.com +17193017642 | H9: 3
A10: 10918908 | B10: 45991 | C10: Tea Stewart | D10: Team Haase-Alvey | E10: 94355 | F10: Sanaa Dighe | G10: Hi Saurabh, I'm excited to reach out to celebrate Sanaaâ€™s amazing progress. Sanaa has worked diligently this semester, and as a result, she scored a 1270 on her PSAT. This is a strong milestone that reflects her effort, consistency, and growth across both math and English skills. I am so proud of the work she has put in and the confidence she is building. Sanaa has shown clear strengths in several areas. In math, she has demonstrated strong familiarity with Desmos functions, has been successful solving for constants of linear functions using Desmos when given points, and has shown solid understanding of special angle relationships involving parallel lines. She has also excelled at setting up equations to determine unknown side lengths and angle measures, as well as setting up proportions for similar shapes. Additionally, she consistently extracts key information from a variety of math problems, which is a major skill for both the SAT and her math coursework. In English, Sanaa has shown strong command of identifying conjunctions, distinguishing between independent and dependent clauses, and applying apostrophe rules accurately. These foundational grammar skills have greatly helped her improve her sentence structure and overall writing clarity. While we are celebrating these successes, there is still targeted work ahead as Sanaa continues preparing for upcoming assessments and the SAT. In math, she will continue improving her approach to multi-condition word problems, strengthening her understanding of similar triangle properties, and finding unknown side lengths. We will also continue reinforcing her understanding of trigonometric relationships so she does not mix up when to use sine, cosine, or tangent. Next session, we will begin working more deeply on triangle trigonometry to extend these skills. In English, Sanaa will continue practicing the three ways to combine two complete sentences, improving her understanding of comma rules, and strengthening her ability to distinguish independent and dependent clauses in more complex sentence structures. She will also benefit from additional practice with transition questions, specifically determining whether clauses are in agreement or disagreement, and from eliminating punctuation-based answer choices more strategically. I am looking forward to continuing to work with Sanaa toward further improvements. I recommend maintaining our current 60 minute weekly sessions so she can continue steady progress toward her next goals, particularly as we begin deeper SAT-level grammar and math strategy work. Sanaa has worked incredibly hard, and her results truly reflect that effort. Iâ€™m excited to keep supporting her as she moves toward her next academic milestones. Please reach out if you have additional questions. Tea S. tea.stewart@revolutionprep.com +17193017642 | H10: 4
A11: 10918913 | B11: 45991 | C11: Myles Oldroyd | D11: Team Plamondon | E11: 90993 | F11: Nicolas Dellarocca | G11: Dear Chris and Kim, Itâ€™s been great working with you and Nico over the past month. As we prepare for Nico's upcoming December SAT, I wanted to share some updates and information about what to expect. I have seen significant improvements in Nico's transitions, measures of central tendency, and word problems. They have shown consistent progress in homework completion, practice tests, and confidence. This consistent improvement has been evident in their continued growth and steady performance across recent practice tests. For this exam, our goal is 1500. While we cannot guarantee a specific score, we have worked diligently towards this goal through IESME, B-PRIMES, and Title 10. It's important to consider the impact of the test zone on Nico's performance. Ensuring a good night's sleep throughout the week leading up to the test is crucial, as just the night before isn't enough. We have also discussed strategies to manage test anxiety, which can impact scores. I am looking forward to hearing how Nico performs on this test. Nico currently has one hour remaining in his account that is unscheduled. Please let me know if you have any questions or if there are any adjustments you would like to make to our plan. Iâ€™m also able to schedule a time to talk by phone if that would be helpful. I am happy to support Nico in their continued academic journey. Thank you and stay safe, Myles O. myles.oldroyd@revolutionprep.com +15304434701 | H11: 1
A12: 10918921 | B12: 45991 | C12: Jason Noble | D12: Team Haase-Alvey | E12: 94893 | F12: Abel Uriostegui | G12: Dear Brittney Uriostegui, I hope you are having a great fall season. Itâ€™s been great working with you and Abel over the past couple of months. I wanted to touch base to share some of the progress weâ€™ve made so far and share my thoughts on the plan moving forward. I have seen significant improvements in Abelâ€™s understanding of decimals, fractions, and foundational algebraic skills. He has shown consistent progress in multiplying and dividing decimals, working with exponents and radicals, solving one-step equations (both standalone and in word problems), and applying operations with positive and negative numbers. This consistent improvement has been evident in his ability to work through increasingly challenging problems, his accuracy with proportional relationships and factors, and his successful transition from proportions into multi-step multiplication, including multiplying within the hundreds. Our current short-term goals for Abel include reinforcing his proportional reasoning, strengthening his fluency with operations involving rational numbers, and continuing to develop his confidence as we introduce more advanced pre-algebra concepts. The overall goal remains keeping him working at an advanced level and preparing him for continued success in higher-level math. Based on Abelâ€™s progress, I recommend continuing to meet for one hour each weekâ€”either as two 30-minute sessions on Monday and Wednesday or as a single one-hour session. This schedule supports steady, accelerated growth and gives Abel consistent practice as he advances into more rigorous material. If you'd like to continue working together on achieving these goals, you can easily use this link to add the hours to your account today: https://my.revolutionprep.com/s/7cHIgWpgJo. Please let me know if you have any questions or if there are any adjustments you would like to make to our plan. Iâ€™m happy to schedule a time to talk by phone if that would be helpful. I look forward to supporting Abel in his continued academic journey. Best regards, Jason N. jason.noble@revolutionprep.com +12162627470 | H12: 4
A13: 10918923 | B13: 45991 | C13: Jason Noble | D13: Team Haase-Alvey | E13: 88830 | F13: Noah Antonio Magana | G13: Dear Tricia Marie Nepomuceno, I hope you are having a great fall season. Itâ€™s been great working with you and Noah over the past couple of months. I wanted to touch base to share some of the progress weâ€™ve made so far and share my thoughts on the plan moving forward. I have seen significant improvements in Noahâ€™s punctuation, grammar, and ability to complete and edit his school assignments. He has shown consistent progress in working through his homework, reviewing grammar concepts, practicing journaling, and building his confidence with both reading and writing tasks. This consistent improvement has been evident in his increased independence with school assignments, his completion of editing practice, and his engagement in introductory Python coding lessons. Our current short-term goals for Noah include continuing to complete school assignments on time, strengthening his reading comprehension through summary writing, and further developing his narrative and academic writing clarity. The overall goal remains improving his confidence and skills in writing, reading comprehension, andâ€”if he choosesâ€”his progression through Python coding units. Based on Noahâ€™s progress, I recommend continuing to meet once a week for one hour to focus on his school assignments or, when he has no homework, to practice reading passages and summarizing them to further improve his writing skills. If he would like to continue learning Python, we can meet once a week for that as well, though those sessions should remain separate to keep each focus area structured and effective. If you'd like to continue working together on achieving these goals, you can redeem more credits through your Bright Horizon's portal. After you redeem your credits, you will receive an email from Revolution Prep to add the hours to your account. Please let me know if you have any questions or if there are any adjustments you would like to make to our plan. Iâ€™m happy to schedule a time to talk by phone if that would be helpful. I look forward to supporting Noah in his continued academic journey. Best regards, Jason N. jason.noble@revolutionprep.com +12162627470 | H13: 4
... A5006: 10862381 | B5006: 45921 | C5006: Zoe Shanley | D5006: Team Plamondon | E5006: 91769 | F5006: Michael Gumino | G5006: Hi Tiffany and Michael, I hope you are well. I wanted to touch base on Michael's progress and discuss the plan moving forward since his test date is coming up quickly. Michael has shown significant improvement in answering questions efficiently in session. He is improving his grammar and punctuation skills as well as fine tuning his already well rounded math skills. I really appreciate the work he has put into our sessions and outside our sessions. I had Michael take a practice exam recently in which he scored an 1140. I am proud of his work; however, with the SAT date coming nearer, and us only having two hours left of sessions scheduled before the test, I wanted to reach out with some thoughts on what I think we should do to get him to the score he wants. In these last two weeks leading up to the test, I would like to recommend that he schedule more hours with me if this is something that works for his availability. Michael is a great student, and he absolutely has the ability to score well on the SAT. I would ideally recommend 3-4 this week and 3-4 hours next week before the test date to get him to his goal. If this is not a feasible schedule adjustment, I am happy to talk more about what we can do to get Michael to his goal. If you would like to discuss more, I am happy to schedule a phone or zoom call. Best, Zoe Zoe S. zoe.shanley@revolutionprep.com +16362488201 | H5006: 3
A5007: 10918864 | B5007: 45991 | C5007: Christine Santos | D5007: Team Cross | E5007: 85148 | F5007: Lev Wechselblatt | G5007: Hi Daniella, I hope youâ€™re doing well! I wanted to share an update on Levâ€™s recent progress as he prepares for the ACT. During our last session, Lev and I reviewed the questions he missed from his recent practice test. Iâ€™m happy to report that he showed considerable improvement in the â€œstudent as editorâ€ questionsâ€”an area weâ€™ve been focusing on, and itâ€™s wonderful to see that our hard work is paying off. Levâ€™s continued progress in this area will serve him well on the actual test. We also identified several more questions, particularly in the science section and the English sectionâ€™s punctuation items, that Lev can easily capture for additional points. To support this, my recommendation is that we begin incorporating more mixed review, focusing on strategies for different science passages and targeted practice with punctuation rules in the English section. Weâ€™ll also be building in timing limits during our practice sessions to help Lev balance his time effectively and minimize rushing or simple mistakes. Despite a few missed questions, Lev performed very well on this last practice test, and Iâ€™m confident that he has all the skills needed to succeed on test dayâ€”itâ€™s just a matter of bringing everything together. If you have any questions or would like to discuss Levâ€™s progress further, please feel free to reach out by email or text. Iâ€™m always happy to help! Thank you, and I look forward to continuing to support Lev! Christine S. christine.santos@revolutionprep.com +19415649546
A5008: 10918868 | B5008: 45991 | C5008: Kristen Luigart | D5008: Team Plamondon | E5008: 89581 | F5008: Yasmine Hammami | G5008: Good evening Kirsten, First off, it was lovely to meet Yasmine this week, she's such a passionate and vibrant young lady, and I wanted to say that she was an absolute pleasure to work with! Yasmine approached the whole essay editing process with maturity and impressive self-awareness. We started this week's session by reading through all of Yasmineâ€™s PIQs, and I provided in-text comments on each. However, we ended up spending majority of our time focusing on the PIQ about her NYT program experience and her personal connection to communication, journalism, and journalistic integrity. When we began, this PIQ had strong ideas but lacked direction and clarity. The opening framed her identity as a â€œglobal writerâ€ and referenced AP English, Mock Trial, and her New York Times coursework equallyâ€”accomplishments that are truly impressive, but in the original draft appeared more as a list than a cohesive, compelling story. The essay needed specificity, stronger organization, and more â€œshow, donâ€™t tell.â€ Together, we reshaped the PIQ into a much more focused and powerful narrative. Yasmine now shares a concrete story about her personal passion for using journalism and communication to correct biased media coverage of Tunisia and the world. This shift allowed her to highlight meaningful experiences and connect them directly to her academic and professional goals. The revised essay includes vivid, authentic detailsâ€”such as using PeopleFinder, interviewing techniques, and NYT archival researchâ€”that demonstrate her initiative, curiosity, and early commitment to journalistic integrity. The new structure paints a clear picture of the work she has done and shows readers exactly why her passion is real and hard-earned. Yasmine made excellent progress in just one session, and I believe continuing to refine any college essays with consistent guidance will only make her applications stronger. I recommend meeting once weekly for one hour as needed to support any additional revisions or new essays she may need to complete for her last few applications. If youâ€™d like to discuss Yasmineâ€™s work or next steps, Iâ€™d be happy to schedule a Zoom or phone call at your convenience. Happy Thanksgiving!Â Kristen Luigart, M.Ed., M.A. kristen.luigart@revolutionprep.com +13018205071
A5009: 10918889 | B5009: 45991 | C5009: Kristen Luigart | D5009: Team Plamondon | E5009: 83525 | F5009: Loui Takahashi | G5009: Good Morning Ippei, I'm writing to give you a bit of a wrap up of all the work Loui and I have done in her tutoring sessions so far. Loui's been working extremely hard (especially with all she has going on in school and out), and her ambitious and passionate nature reflects in her writing and intelligence. Together, we have now completed Loui's personal essay, as well as her supplemental essays for Yale, the University of Vermont, Tufts, and -- most recently -- UC Berkeley, which we just finalized with only a little time to spare. Despite the tight timeline, her Berkeley essays turned out excellent. Loui's writing has a strong, innate, sense of storytelling, and a compelling voice to begin with, so working with her on her essays has really been about giving more immediacy and vibrancy to the works. (And sometimes helping her find the motivation to be passionate about some truly awful prompts! ;3) Throughout all the essays, we have focused on strengthening Loui's language and composition to create more compelling narrative flow, express more passion, and illustrate with greater clarity. The key to a good college application essay is being able to use only a couple hundred words to become a fully-fleshed out being to the numbed essay readers at university admissions. With hundreds of thousands of students applying to schools every year, essay readers tend to zone out quickly when essays are repetitive or rote. (I have personal experience with this from being the chair of admissions for UVA's honors dorm, Brown College, which had its own rigorous application essay process.) Therefore, to break through the monotonous repetition of the usual accomplishment lists draped in prose disguised as essays, a student must not only answer their prompts intelligently -- but compellingly, in order to rise above the simple 'fulfilled requirement' stack. I am confident that the essays Loui has brought from this program have all had that spark, and that they use it effectively to highlight how impressive and multifaceted Loui is as an applicant. A good example of this editing process can be seen in how, when we first reviewed Loui's Berkeley drafts, she and I both found them to come across as flat and lacking passion. The prompt, itself, was relatively dry, and without finding a way to feel passionate about the subject, Loui's work came out as simply informative and somewhat distanced. The essays read more like reports than personal reflections. Over several rounds of revision, Loui transformed them all into essays that are far more authentic, vital, and emotionally grounded. For example, the new essay on social mediaâ€™s impact on Loui's life, and her subsequent rejection of it, presents compelling statisticsâ€”such as 5.3 billion selfies are taken per day â€” that highlight Loui's wisdom in learning how to "put down the light-up brick". These striking facts, and the additional comments on the human history of appearance, helped anchor Loui's narrative in something both memorable and meaningful. With Berkeley completed, our next priority is Johns Hopkins. Brainstorming for its essays is Loui's homework for our next session on December 13. After that, we will continue on with her essays for Bowdoin, CMU, and the University of Chicago. To ensure Loui stays comfortably ahead of all deadlines, and maintains her strong momentum, I recommend meeting at least once a week for an hour until all remaining essays are completed. (Ideally, therefore, they will be finished well before their due dates). If youâ€™d like to discuss Louiâ€™s progress or upcoming plans, I would be happy to schedule a Zoom or phone call at your convenience. Warm regards, and Happy Thanksgiving! Kristen Luigart, M.Ed., M.A. Kristen.Luigart@Revolutionprep.com (301)*20-5071
A5010: 10918896 | B5010: 45991 | C5010: Myles Oldroyd | D5010: Team Plamondon | E5010: 90236 | F5010: Brooks Main | G5010: Dear Clayton, Itâ€™s been great working with you and Brooks over the past two months. As we prepare for Brooks's upcoming December SAT, I wanted to share some updates and information about what to expect. I have seen significant improvements in Brooks's two passage reading, measures of central tendency, main ideas, and interpreting equations. They have shown consistent progress in homework and practice tests. This consistent improvement has been evident in a new high score on a practice test of 1440. For this exam, our goal is 1500. While we cannot guarantee a specific score, we have worked diligently towards this goal through B-PRIMES, Title 10, and IESME. It's important to consider the impact of the test zone on Brooks's performance. Ensuring a good night's sleep throughout the week leading up to the test is crucial, as just the night before isn't enough. We have also discussed strategies to manage test anxiety, which can impact scores. I am looking forward to continuing to work with Brooks after the test so that we can work towards further improvements on the SAT. I recommend maintaining at least one session a week until Brooks is happy with his score in order to help them achieve their goals. Please let me know if you have any questions or if there are any adjustments you would like to make to our plan. Iâ€™m also able to schedule a time to talk by phone if that would be helpful. I am happy to support Brooks in their continued academic journey. Thank you and stay safe, Myles O. myles.oldroyd@revolutionprep.com +15304434701
A5011: 10918902 | B5011: 45991 | C5011: Myles Oldroyd | D5011: Team Plamondon | E5011: 83644 | F5011: Reese Migdal | G5011: Dear Kristina, I hope youâ€™re doing well. I wanted to share an update on Reeseâ€™s progress over the past two months and outline our plan moving forward. Over the last two months, Reese has shown meaningful improvement in command of textual evidence, central ideas and details, and trigonometric identities.While working on precalc, Reese seemed to grasp how to view trigonometric identities as a puzzle to solve rather than an annoyance to complete. Our goals over the next phase of instruction include continuing to build his SAT readiness, deepening mastery of reading skills, and ensuring Reese feels confident applying these skills independently. To support this, I recommend regular sessions of at least once a week to prepare for the SAT and keep up with his math course. In the coming sessions, I plan to focus on the reading portion of the SAT including reading comprehension and data analysis, while continuing to reinforce previous learning targets. If you have any questions or if there are adjustments youâ€™d like to make to our plan, please feel free to reach out. Iâ€™m happy to schedule a call if that would be helpful. Thank you for your continued partnership. Itâ€™s a pleasure working with Reese and supporting his academic growth. Thank you and stay safe, Myles O. myles.oldroyd@revolutionprep.com +15304434701
A5012: 10918905 | B5012: 45991 | C5012: Tea Stewart | D5012: Team Haase-Alvey | E5012: 81932 | F5012: Oscar Anguiano | G5012: Hi Oscar, I hope you are having a great fall season. Itâ€™s been wonderful working with you and Oscar over the past couple of months. I wanted to take a moment to share some of the progress weâ€™ve made so far and outline my thoughts moving forward. I have seen significant improvements in Oscarâ€™s understanding and application of graph transformations, particularly with horizontal shifts. Over the semester, he has become much more confident identifying when a function is moving left or right and applying that knowledge accurately in practice problems. In addition, Oscar has shown strong growth in his work with similar triangle ratios. He consistently sets up correct proportions and demonstrates a solid understanding of how corresponding sides relate, which has been a highlight of his progress. His willingness to ask questions and revisit challenging problems has been one of the biggest contributors to this growth, and Iâ€™ve seen his confidence increase as a result. Our current short-term goals for Oscar include strengthening his understanding of function notation, learning to distinguish between stretches and compressions, and accurately identifying reflections across the x- and y-axis. In geometry, short-term goals also include improving his ability to solve proportions that lead to quadratic equations and deepening his understanding of geometric means within triangle relationships. The overall goal remains building Oscarâ€™s confidence and mastery in algebra and geometry so he feels prepared and capable in his math coursework. Based on Oscarâ€™s progress, I suggest we continue with our weekly 60-minute sessions moving forward. Overall, Oscar has worked hard throughout the semester, and his progress and grades reflects that effort. I look forward to continuing to support his growth in these areas. Please feel free to reach out if you have any questions or would like additional updates. Tea S. tea.stewart@revolutionprep.com +17193017642
A5013: 10918906 | B5013: 45991 | C5013: Tea Stewart | D5013: Team Haase-Alvey | E5013: 78245 | F5013: Noor El-Helw | G5013: Hi Dania, I hope you are having a great fall season. Itâ€™s been wonderful working with you and Noor over the past couple of months. I wanted to take a moment to share some of the progress weâ€™ve made so far and outline my thoughts moving forward. I have seen significant improvements in Noorâ€™s understanding and setup of improper integrals. She has consistently demonstrated the ability to recognize when an integral requires limits or a domain adjustment, and her accuracy in forming the correct limit expressions has strengthened throughout the semester. Noor has also done well with tangent line equations for parametric functions, showing confidence in applying derivatives correctly to construct linear approximations. Additionally, she has shown strong mastery in working with speed and velocity vectors of parametric functions, as well as selecting appropriate radian values to construct polar coordinate tables. In integration, Noor has done excellent work eliminating factors to determine unknown constants for partial fractions, a skill that has noticeably improved her efficiency and accuracy. Noor continues to work on several more advanced skills appropriate for Calculus BC. We will focus on strengthening her ability to determine when an improper integral converges or diverges, as well as developing clearer instincts on when extended Lâ€™HÃ´pitalâ€™s Rule is appropriate. She will also benefit from more targeted practice finding vertical and horizontal tangent lines for parametric curves. In polar coordinates, Noorâ€™s next steps include improving her graphing of polar functions with negative r-values and building confidence in interpreting their directional behavior. For integration, she will continue to work on simplifying improper rational expressions before applying partial fractions. We will also devote additional time to solving for t in complex trigonometric equations, an area that will benefit from repeated structured practice. Our current short-term goals for Noor include strengthening her convergence/divergence reasoning, mastering tangent line behavior in parametric curves, and improving clarity with both polar graphing techniques and trigonometric equation solving. The overall goal remains to build Noorâ€™s confidence and mastery across all BC topics so she feels fully prepared for assessments and the AP Exam. Based on Noorâ€™s progress, I recommend maintaining our current schedule of two 60-minute sessions to support steady development as we move into more challenging units. Noor has shown consistent effort throughout the semester, and her progress reflects that dedication. I look forward to continuing to support her growth in these areas. Please feel free to reach out if you have any questions or would like additional updates. Tea S. tea.stewart@revolutionprep.com +17193017642
A5014: 10918907 | B5014: 45991 | C5014: Tea Stewart | D5014: Team Haase-Alvey | E5014: 91642 | F5014: Gavin Gardner | G5014: Hi Shanna, I hope you are having a great fall season. Itâ€™s been wonderful working with you and Gavin over the past couple of months. I wanted to take a moment to share some of the progress weâ€™ve made so far and outline my thoughts moving forward. I have seen improvements in Gavinâ€™s ability to solve systems of equations. He has become more confident setting up equations, choosing appropriate methods, and checking his work for accuracy. Gavin has also done well using the Desmos linear regression formula to analyze linear relationships and interpret results correctly, which has strengthened his problem-solving skills in algebra. In English, he has shown strong progress identifying introductory phrases, demonstrating a clearer understanding of sentence structure and grammatical components. Moving forward, Gavin will continue working on several key areas. In math, he will benefit from becoming more comfortable with the functions and tools embedded within Desmos, which will help him work more efficiently and accurately during assignments. In writing, he will continue developing his ability to combine two complete sentences using the three correct methodsâ€”comma + coordinating conjunction, semicolon, or a period. Improving consistency with these skills will support his clarity and correctness in written communication. Additionally, we will focus on building stronger habits around homework completion, especially avoiding last-minute work so he can focus on quality and comprehension. Our current short-term goals for Gavin include strengthening his command of the three ways to combine complete sentences, improving his use of Desmos tools, and establishing consistent homework routines. The overall goal remains building Gavinâ€™s confidence, accuracy, and independence across his math and writing tasks. Based on Gavinâ€™s progress, I recommend we maintain our current schedule of weekly 60-minute sessions to support steady growth while continuing to reinforce foundational skills. I look forward to continuing to support his growth in these areas. Please feel free to reach out if you have any questions or would like additional updates. Tea S. tea.stewart@revolutionprep.com +17193017642
