Workbook

Sheet MonthlyMetric
A1: Tutor Name | B1: Tier | C1: Adjunct/Professional | D1: Faculty Leader | E1: Date Range | F1: % to Delivery Target | G1: % to Availability Target | H1: % Sessions on Time | I1: % Parents Updates Done on Time | J1: % of Active Students with Progress Updates Completed in last 2 months | K1: Weighted Repurchases | L1: OLD PPW | M1: Ratio of PPW Events with Attached PPWs
A2: Aaron Schneberger | B2: =VLOOKUP(A2,MasterTutor!A:E,4,FALSE) -> Advanced | C2: =VLOOKUP(A2,MasterTutor!A:E,3,FALSE) -> Adjunct | D2: =VLOOKUP(A2,MasterTutor!A:E,2,FALSE) -> Ian Plamondon | E2: 1/26/25 - 2/22/25 | F2: 1.07 | G2: 1.06 | H2: 1 | I2: 1 | J2: 0.828 | K2: 9 | L2: 0.5 | M2: =L2 -> 0.5
A3: Aidan Thomason | B3: =VLOOKUP(A3,MasterTutor!A:E,4,FALSE) -> #N/A | C3: =VLOOKUP(A3,MasterTutor!A:E,3,FALSE) -> #N/A | D3: =VLOOKUP(A3,MasterTutor!A:E,2,FALSE) -> #N/A | E3: 1/26/25 - 2/22/25 | F3: 1.08 | G3: 1.14 | H3: 0.886 | I3: 1 | J3: 0.583 | K3: 2
A4: Akeema Williams | B4: =VLOOKUP(A4,MasterTutor!A:E,4,FALSE) -> Advanced | C4: =VLOOKUP(A4,MasterTutor!A:E,3,FALSE) -> Professional | D4: =VLOOKUP(A4,MasterTutor!A:E,2,FALSE) -> Ian Plamondon | E4: 1/26/25 - 2/22/25 | F4: 0.97 | G4: 1.01 | H4: 1 | I4: 1 | J4: 0.32 | K4: 6 | L4: 0 | M4: =L4 -> 0
A5: Alex Small | B5: =VLOOKUP(A5,MasterTutor!A:E,4,FALSE) -> Premium | C5: =VLOOKUP(A5,MasterTutor!A:E,3,FALSE) -> Adjunct | D5: =VLOOKUP(A5,MasterTutor!A:E,2,FALSE) -> Ela Cross | E5: 1/26/25 - 2/22/25 | F5: 0.99 | G5: 1 | H5: 1 | I5: 1 | J5: 0.778 | K5: 1 | L5: 1 | M5: =L5 -> 1
A6: Alexa Pinera | B6: =VLOOKUP(A6,MasterTutor!A:E,4,FALSE) -> Premium | C6: =VLOOKUP(A6,MasterTutor!A:E,3,FALSE) -> Professional | D6: =VLOOKUP(A6,MasterTutor!A:E,2,FALSE) -> Ian Plamondon | E6: 1/26/25 - 2/22/25 | F6: 1.16 | G6: 1.13 | H6: 0.9827 | I6: 1 | J6: 0.737 | K6: 0 | L6: 1 | M6: =L6 -> 1
A7: Alexis Boucher | B7: =VLOOKUP(A7,MasterTutor!A:E,4,FALSE) -> Distinguished | C7: =VLOOKUP(A7,MasterTutor!A:E,3,FALSE) -> Professional | D7: =VLOOKUP(A7,MasterTutor!A:E,2,FALSE) -> Ian Plamondon | E7: 1/26/25 - 2/22/25 | F7: 1.04 | G7: 1.02 | H7: 1 | I7: 1 | J7: 1 | K7: 5 | L7: 1 | M7: =L7 -> 1
A8: Alison Trumbull | B8: =VLOOKUP(A8,MasterTutor!A:E,4,FALSE) -> Premium | C8: =VLOOKUP(A8,MasterTutor!A:E,3,FALSE) -> Adjunct | D8: =VLOOKUP(A8,MasterTutor!A:E,2,FALSE) -> Geoff St. Marie | E8: 1/26/25 - 2/22/25 | F8: 1.39 | G8: 1.19 | H8: 1 | I8: 0.9565 | J8: 0.917 | K8: 2
A9: Alli Winkelmann | B9: =VLOOKUP(A9,MasterTutor!A:E,4,FALSE) -> #N/A | C9: =VLOOKUP(A9,MasterTutor!A:E,3,FALSE) -> #N/A | D9: =VLOOKUP(A9,MasterTutor!A:E,2,FALSE) -> #N/A | E9: 1/26/25 - 2/22/25 | F9: 1.38 | G9: 1.2 | H9: 0.9706 | I9: 0.9811 | J9: 1 | K9: 4 | L9: 0.8 | M9: =L9 -> 0.8
A10: Allison Peck | B10: =VLOOKUP(A10,MasterTutor!A:E,4,FALSE) -> Distinguished | C10: =VLOOKUP(A10,MasterTutor!A:E,3,FALSE) -> Adjunct | D10: =VLOOKUP(A10,MasterTutor!A:E,2,FALSE) -> Kristin Haase-Alvey | E10: 1/26/25 - 2/22/25 | F10: 0.99 | G10: 1.19 | H10: 1 | I10: 0.9355 | J10: 1 | K10: 3 | L10: 1 | M10: =L10 -> 1
A11: Amber Maldonado | B11: =VLOOKUP(A11,MasterTutor!A:E,4,FALSE) -> Advanced | C11: =VLOOKUP(A11,MasterTutor!A:E,3,FALSE) -> Professional | D11: =VLOOKUP(A11,MasterTutor!A:E,2,FALSE) -> Annelies de Groot | E11: 1/26/25 - 2/22/25 | F11: 0.41 | G11: 0.88 | H11: 1 | I11: 0.9412 | J11: 0.563 | K11: #N/A | L11: 0.33333333 | M11: =L11 -> 0.33333333
A12: Amelia Sain | B12: =VLOOKUP(A12,MasterTutor!A:E,4,FALSE) -> Premium | C12: =VLOOKUP(A12,MasterTutor!A:E,3,FALSE) -> Professional | D12: =VLOOKUP(A12,MasterTutor!A:E,2,FALSE) -> Jessica Milner | E12: 1/26/25 - 2/22/25 | F12: 0.76 | G12: 1.25 | H12: 1 | I12: 0.9412 | J12: 0.167 | K12: #N/A | L12: 0 | M12: =L12 -> 0
A13: Ana Heiser | B13: =VLOOKUP(A13,MasterTutor!A:E,4,FALSE) -> Distinguished | C13: =VLOOKUP(A13,MasterTutor!A:E,3,FALSE) -> Professional | D13: =VLOOKUP(A13,MasterTutor!A:E,2,FALSE) -> Kristin Haase-Alvey | E13: 1/26/25 - 2/22/25 | F13: 1.01 | G13: 1.01 | H13: 1 | I13: 0.7658 | J13: 0.842 | K13: 5 | L13: 1 | M13: =L13 -> 1
A14: Andrea Comstock | B14: =VLOOKUP(A14,MasterTutor!A:E,4,FALSE) -> #N/A | C14: =VLOOKUP(A14,MasterTutor!A:E,3,FALSE) -> #N/A | D14: =VLOOKUP(A14,MasterTutor!A:E,2,FALSE) -> #N/A | E14: 1/26/25 - 2/22/25 | F14: 1.25 | G14: 1.11 | H14: 1 | I14: 0.6825 | J14: 0.615 | K14: 7 | L14: 0 | M14: =L14 -> 0
A15: Andrew Brown | B15: =VLOOKUP(A15,MasterTutor!A:E,4,FALSE) -> Distinguished | C15: =VLOOKUP(A15,MasterTutor!A:E,3,FALSE) -> Professional | D15: =VLOOKUP(A15,MasterTutor!A:E,2,FALSE) -> Ian Plamondon | E15: 1/26/25 - 2/22/25 | F15: 0.99 | G15: 1.09 | H15: 0.9828 | I15: 0.9342 | J15: 0.632 | K15: 4 | L15: 0.66666667 | M15: =L15 -> 0.66666667
A16: Andrew Gehlot | B16: =VLOOKUP(A16,MasterTutor!A:E,4,FALSE) -> Premium | C16: =VLOOKUP(A16,MasterTutor!A:E,3,FALSE) -> Professional | D16: =VLOOKUP(A16,MasterTutor!A:E,2,FALSE) -> Jessica Milner | E16: 1/26/25 - 2/22/25 | F16: 0.78 | G16: 1.1 | H16: 0.9868 | I16: 0.9074 | J16: 0.769 | K16: 6 | L16: 1 | M16: =L16 -> 1
A17: Angelina Guzman | B17: =VLOOKUP(A17,MasterTutor!A:E,4,FALSE) -> #N/A | C17: =VLOOKUP(A17,MasterTutor!A:E,3,FALSE) -> #N/A | D17: =VLOOKUP(A17,MasterTutor!A:E,2,FALSE) -> #N/A | E17: 1/26/25 - 2/22/25 | F17: 1.06 | G17: 1.06 | H17: 0.961 | I17: 0.9709 | J17: 0.808 | K17: 14 | L17: 1 | M17: =L17 -> 1
A18: Anna Gilbert | B18: =VLOOKUP(A18,MasterTutor!A:E,4,FALSE) -> Distinguished | C18: =VLOOKUP(A18,MasterTutor!A:E,3,FALSE) -> Adjunct | D18: =VLOOKUP(A18,MasterTutor!A:E,2,FALSE) -> Kristin Haase-Alvey | E18: 1/26/25 - 2/22/25 | F18: 0.9 | G18: 0.83 | H18: 1 | I18: 0.9775 | J18: 0.857 | K18: 13 | L18: 1 | M18: =L18 -> 1
A19: Armand Brouty | B19: =VLOOKUP(A19,MasterTutor!A:E,4,FALSE) -> Distinguished | C19: =VLOOKUP(A19,MasterTutor!A:E,3,FALSE) -> Professional | D19: =VLOOKUP(A19,MasterTutor!A:E,2,FALSE) -> Ian Plamondon | E19: 1/26/25 - 2/22/25 | F19: 1.01 | G19: 1.68 | H19: 0.9714 | I19: 1 | J19: 0.958 | K19: 3 | L19: 0.85714286 | M19: =L19 -> 0.85714286
A20: Aryan Jazayeri | B20: =VLOOKUP(A20,MasterTutor!A:E,4,FALSE) -> Premium | C20: =VLOOKUP(A20,MasterTutor!A:E,3,FALSE) -> Adjunct | D20: =VLOOKUP(A20,MasterTutor!A:E,2,FALSE) -> Kristin Haase-Alvey | E20: 1/26/25 - 2/22/25 | F20: 0.93 | G20: 0.95 | H20: 1 | I20: 1 | J20: 0.667 | K20: #N/A | L20: 1 | M20: =L20 -> 1
A21: Ashley Lang | B21: =VLOOKUP(A21,MasterTutor!A:E,4,FALSE) -> #N/A | C21: =VLOOKUP(A21,MasterTutor!A:E,3,FALSE) -> #N/A | D21: =VLOOKUP(A21,MasterTutor!A:E,2,FALSE) -> #N/A | E21: 1/26/25 - 2/22/25 | F21: 0.98 | G21: 1 | H21: 0.9752 | I21: 0.977 | J21: 0.1 | K21: 2 | L21: 0 | M21: =L21 -> 0
A22: Ashley Scorsone | B22: =VLOOKUP(A22,MasterTutor!A:E,4,FALSE) -> Premium | C22: =VLOOKUP(A22,MasterTutor!A:E,3,FALSE) -> Professional | D22: =VLOOKUP(A22,MasterTutor!A:E,2,FALSE) -> Geoff St. Marie | E22: 1/26/25 - 2/22/25 | F22: 1.33 | G22: 1.46 | H22: 0.9046 | I22: 0.6837 | J22: 0.654 | K22: 5 | L22: 0 | M22: =L22 -> 0
A23: Asiyah Ahmed | B23: =VLOOKUP(A23,MasterTutor!A:E,4,FALSE) -> #N/A | C23: =VLOOKUP(A23,MasterTutor!A:E,3,FALSE) -> #N/A | D23: =VLOOKUP(A23,MasterTutor!A:E,2,FALSE) -> #N/A | E23: 1/26/25 - 2/22/25 | F23: 1.07 | G23: 0.9 | H23: 0.9808 | I23: 0.84 | J23: 0.688 | K23: 3 | L23: 0 | M23: =L23 -> 0
A24: Ayman Smoot | B24: =VLOOKUP(A24,MasterTutor!A:E,4,FALSE) -> Advanced | C24: =VLOOKUP(A24,MasterTutor!A:E,3,FALSE) -> Adjunct | D24: =VLOOKUP(A24,MasterTutor!A:E,2,FALSE) -> Annelies de Groot | E24: 1/26/25 - 2/22/25 | F24: 1.59 | G24: 2.34 | H24: 0.9881 | I24: 0.8909 | J24: 0.333 | K24: 2 | L24: 0.5 | M24: =L24 -> 0.5
A25: Ben Taylor | B25: =VLOOKUP(A25,MasterTutor!A:E,4,FALSE) -> Premium | C25: =VLOOKUP(A25,MasterTutor!A:E,3,FALSE) -> Professional | D25: =VLOOKUP(A25,MasterTutor!A:E,2,FALSE) -> Jessica Milner | E25: 1/26/25 - 2/22/25 | F25: 0.84 | G25: 1.08 | H25: 1 | I25: 1 | J25: 0.471 | K25: 2
A26: Blake Johnson | B26: =VLOOKUP(A26,MasterTutor!A:E,4,FALSE) -> #N/A | C26: =VLOOKUP(A26,MasterTutor!A:E,3,FALSE) -> #N/A | D26: =VLOOKUP(A26,MasterTutor!A:E,2,FALSE) -> #N/A | E26: 1/26/25 - 2/22/25 | F26: 0.97 | G26: 0.88 | H26: 0.9542 | I26: 0.9722 | J26: 0.667 | K26: 1
A27: Brenna Hubnik | B27: =VLOOKUP(A27,MasterTutor!A:E,4,FALSE) -> Advanced | C27: =VLOOKUP(A27,MasterTutor!A:E,3,FALSE) -> Adjunct | D27: =VLOOKUP(A27,MasterTutor!A:E,2,FALSE) -> Annelies de Groot | E27: 1/26/25 - 2/22/25 | F27: 2.03 | G27: 2.06 | H27: 0.9863 | I27: 0.989 | J27: 0.68 | K27: 9 | L27: 1 | M27: =L27 -> 1
A28: Brian Cohen | B28: =VLOOKUP(A28,MasterTutor!A:E,4,FALSE) -> Premium | C28: =VLOOKUP(A28,MasterTutor!A:E,3,FALSE) -> Adjunct | D28: =VLOOKUP(A28,MasterTutor!A:E,2,FALSE) -> Jessica Milner | E28: 1/26/25 - 2/22/25 | F28: 0.82 | G28: 0.93 | H28: 1 | I28: 1 | J28: 1 | K28: #N/A | L28: 1 | M28: =L28 -> 1
A29: Brian James | B29: =VLOOKUP(A29,MasterTutor!A:E,4,FALSE) -> Advanced | C29: =VLOOKUP(A29,MasterTutor!A:E,3,FALSE) -> Professional | D29: =VLOOKUP(A29,MasterTutor!A:E,2,FALSE) -> Annelies de Groot | E29: 1/26/25 - 2/22/25 | F29: 1.44 | G29: 1.3 | H29: 1 | I29: 0.8846 | J29: 0.438 | K29: 14 | L29: 0.5 | M29: =L29 -> 0.5
A30: Bryant Salinas | B30: =VLOOKUP(A30,MasterTutor!A:E,4,FALSE) -> Premium | C30: =VLOOKUP(A30,MasterTutor!A:E,3,FALSE) -> Professional | D30: =VLOOKUP(A30,MasterTutor!A:E,2,FALSE) -> Jessica Milner | E30: 1/26/25 - 2/22/25 | F30: 1.05 | G30: 1.1 | H30: 0.9443 | I30: 0.9595 | J30: 0.722 | K30: 3 | L30: 0.66666667 | M30: =L30 -> 0.66666667
A31: Cait White | B31: =VLOOKUP(A31,MasterTutor!A:E,4,FALSE) -> Premium | C31: =VLOOKUP(A31,MasterTutor!A:E,3,FALSE) -> Adjunct | D31: =VLOOKUP(A31,MasterTutor!A:E,2,FALSE) -> Ela Cross | E31: 1/26/25 - 2/22/25 | F31: 0.31 | G31: 1.24 | H31: 1 | I31: 1 | J31: #N/A | K31: #N/A
A32: Camila Calderon | B32: =VLOOKUP(A32,MasterTutor!A:E,4,FALSE) -> #N/A | C32: =VLOOKUP(A32,MasterTutor!A:E,3,FALSE) -> #N/A | D32: =VLOOKUP(A32,MasterTutor!A:E,2,FALSE) -> #N/A | E32: 1/26/25 - 2/22/25 | F32: 1.03 | G32: 1.08 | H32: 0.9715 | I32: 0.9351 | J32: 0.533 | K32: 7 | L32: 1 | M32: =L32 -> 1
A33: Camila Hernandez | B33: =VLOOKUP(A33,MasterTutor!A:E,4,FALSE) -> #N/A | C33: =VLOOKUP(A33,MasterTutor!A:E,3,FALSE) -> #N/A | D33: =VLOOKUP(A33,MasterTutor!A:E,2,FALSE) -> #N/A | E33: 1/26/25 - 2/22/25 | F33: 0.66 | G33: 0.56 | H33: 0.9778 | I33: 1 | J33: 0.375 | K33: 4 | L33: 1 | M33: =L33 -> 1
A34: Camryn To | B34: =VLOOKUP(A34,MasterTutor!A:E,4,FALSE) -> Distinguished | C34: =VLOOKUP(A34,MasterTutor!A:E,3,FALSE) -> Adjunct | D34: =VLOOKUP(A34,MasterTutor!A:E,2,FALSE) -> Kristin Haase-Alvey | E34: 1/26/25 - 2/22/25 | F34: 1.49 | G34: 1.34 | H34: 1 | I34: 1 | J34: 0.846 | K34: 5
A35: Cara Rabaev (McLaughlin) | B35: =VLOOKUP(A35,MasterTutor!A:E,4,FALSE) -> Distinguished | C35: =VLOOKUP(A35,MasterTutor!A:E,3,FALSE) -> Professional | D35: =VLOOKUP(A35,MasterTutor!A:E,2,FALSE) -> Ian Plamondon | E35: 1/26/25 - 2/22/25 | F35: 1.47 | G35: 1.57 | H35: 0.799 | I35: 0.8406 | J35: 0.6 | K35: 10 | L35: 0 | M35: =L35 -> 0
A36: Carson Hsiao | B36: =VLOOKUP(A36,MasterTutor!A:E,4,FALSE) -> #N/A | C36: =VLOOKUP(A36,MasterTutor!A:E,3,FALSE) -> #N/A | D36: =VLOOKUP(A36,MasterTutor!A:E,2,FALSE) -> #N/A | E36: 1/26/25 - 2/22/25 | F36: 1.57 | G36: 1.42 | H36: 1 | I36: 0.9831 | J36: 0.563 | K36: 6 | L36: 1 | M36: =L36 -> 1
A37: Charlie Anderson | B37: =VLOOKUP(A37,MasterTutor!A:E,4,FALSE) -> Advanced | C37: =VLOOKUP(A37,MasterTutor!A:E,3,FALSE) -> Professional | D37: =VLOOKUP(A37,MasterTutor!A:E,2,FALSE) -> Annelies de Groot | E37: 1/26/25 - 2/22/25 | F37: 0.48 | G37: 0.74 | H37: 0.9872 | I37: 0.9286 | J37: 0.765 | K37: #N/A | L37: 0.5 | M37: =L37 -> 0.5
A38: Chazlee Myers | B38: =VLOOKUP(A38,MasterTutor!A:E,4,FALSE) -> Advanced | C38: =VLOOKUP(A38,MasterTutor!A:E,3,FALSE) -> Professional | D38: =VLOOKUP(A38,MasterTutor!A:E,2,FALSE) -> Ian Plamondon | E38: 1/26/25 - 2/22/25 | F38: 0.76 | G38: 0.91 | H38: 0.9027 | I38: 0.8857 | J38: 0.625 | K38: 1 | L38: 0.25 | M38: =L38 -> 0.25
A39: Cheryl Lambert | B39: =VLOOKUP(A39,MasterTutor!A:E,4,FALSE) -> Premium | C39: =VLOOKUP(A39,MasterTutor!A:E,3,FALSE) -> Adjunct | D39: =VLOOKUP(A39,MasterTutor!A:E,2,FALSE) -> Kristin Haase-Alvey | E39: 1/26/25 - 2/22/25 | F39: 0.83 | G39: 1.19 | H39: 0.9792 | I39: 1 | J39: 0.667 | K39: 4 | L39: 1 | M39: =L39 -> 1
A40: Chris Prouty | B40: =VLOOKUP(A40,MasterTutor!A:E,4,FALSE) -> Premium | C40: =VLOOKUP(A40,MasterTutor!A:E,3,FALSE) -> Adjunct | D40: =VLOOKUP(A40,MasterTutor!A:E,2,FALSE) -> Annelies de Groot | E40: 1/26/25 - 2/22/25 | F40: 0.64 | G40: 0.74 | H40: 1 | I40: 0.9167 | J40: 1 | K40: 4
...

Sheet MonthlyMetricFullData
A1: Tutor Name | B1: Current Tier | C1: Faculty Leader Name | D1: Hire Date | E1: Delivery Target | F1: Avg. Delivery Actual | G1: % to Delivery Target | H1: Availability Target | I1: Avg. Availability Actual | J1: % to Availability Target | K1: Prep Time % | L1: % Parents Updates Done on Time | M1: % Sessions on Time | N1: Ratio of PPW Events with Attached PPWs | O1: % of Active Students with Progress Updates Completed | P1: # of NPS Scores | Q1: Avg. NPS Score | R1: Weighted Repurchases | S1: Autoattendance | T1: New 1 on 1 Students | U1: total 1 on 1 students | V1: Average AI Score for Progress Updates
A2: Aaron Schneberger | B2: Advanced | C2: Ian Plamondon | D2: 45524 | E2: 12 | F2: 9.13 | G2: 0.7604 | H2: 16 | I2: 12.44 | J2: 0.7773 | K2: 0.2937 | L2: 1 | M2: 1 | O2: 0.90909091 | R2: 1 | T2: 0 | U2: 13 | V2: 4.4
A3: Akeema Williams | B3: Advanced | C3: Ian Plamondon | D3: 45519 | E3: 30 | F3: 27.75 | G3: 0.925 | H3: 38 | I3: 36.63 | J3: 0.9638 | K3: 0.2914 | L3: 0.97435897 | M3: 0.99193548 | N3: 1/7 | O3: 0.76470588 | P3: 1 | Q3: 10 | R3: 11 | T3: 15 | U3: 42
A4: Alex Small | B4: Premium | C4: Ela Cross | D4: 43907 | E4: 12 | F4: 9.63 | G4: 0.8021 | H4: 16 | I4: 24.56 | J4: 1.5352 | K4: 0.6382 | L4: 0.9 | M4: 1 | O4: 0.875 | R4: 2 | T4: 1 | U4: 11 | V4: #N/A
A5: Alexa Pinera | B5: Premium | C5: Ian Plamondon | D5: 43812 | E5: 30 | F5: 21.04 | G5: 0.7014 | H5: 38 | I5: 75.75 | J5: 1.9934 | K5: 0.0369 | L5: 1 | M5: 0.97101449 | N5: 2/3 | O5: 0.71428571 | R5: 5 | T5: 5 | U5: 17 | V5: 4
A6: Alexandra Berrios | B6: Advanced | C6: Kristin Haase-Alvey | D6: 45755 | E6: 12 | F6: 20.06 | G6: 1.6719 | H6: 16 | I6: 22 | J6: 1.375 | K6: 0.0808 | L6: 0.46969697 | M6: 1 | N6: 0/5 | O6: 0.8125 | P6: 1 | Q6: 1 | R6: 11 | S6: 19 | T6: 10 | U6: 31 | V6: #N/A
A7: Alexis Boucher | B7: Distinguished | C7: Ian Plamondon | D7: 43749 | E7: 30 | F7: 15.13 | G7: 0.5042 | H7: 38 | I7: 34.25 | J7: 0.9013 | K7: 0.0641 | L7: 0.81818182 | M7: 1 | N7: 1/1 | O7: 0.92857143 | P7: 1 | Q7: 10 | R7: 2 | T7: 2 | U7: 17
A8: Alison Trumbull | B8: Premium | C8: Geoff St. Marie | D8: 39309 | E8: 12 | F8: 4.88 | G8: 0.4063 | H8: 16 | I8: 14.44 | J8: 0.9023 | K8: 0.054 | L8: 1 | M8: 0.94444444 | O8: 1 | T8: 1 | U8: 7 | V8: 3
A9: Allison Peck | B9: Distinguished | C9: Kristin Haase-Alvey | D9: 45223 | E9: 12 | F9: 7.75 | G9: 0.6458 | H9: 16 | I9: 16.88 | J9: 1.0547 | K9: 0.1916 | L9: 1 | M9: 0.96666667 | O9: 1 | R9: 2 | T9: 0 | U9: 5 | V9: #N/A
A10: Amber Maldonado | B10: Advanced | C10: Annelies de Groot | D10: 45683 | E10: 30 | F10: 19.75 | G10: 0.6583 | H10: 38 | I10: 35.94 | J10: 0.9457 | K10: 0.3986 | L10: 0.875 | M10: 0.87878788 | N10: 2/4 | O10: 1 | P10: 1 | Q10: 10 | R10: 2 | T10: 4 | U10: 23 | V10: #N/A
A11: Amelia Sain | B11: Premium | C11: Jessica Milner | D11: 43479 | E11: 30 | F11: 14.75 | G11: 0.4917 | H11: 38 | I11: 45 | J11: 1.1842 | K11: 0.123 | L11: 1 | M11: 1 | N11: 0/2 | O11: 0.33333333 | R11: 1 | T11: 3 | U11: 11 | V11: #N/A
A12: Ana Heiser | B12: Distinguished | C12: Kristin Haase-Alvey | D12: 45538 | E12: 30 | F12: 16.88 | G12: 0.5625 | H12: 38 | I12: 38.31 | J12: 1.0082 | K12: 0.1597 | L12: 0.84210526 | M12: 1 | N12: 2/2 | O12: 0.88888889 | R12: 2 | S12: 1 | T12: 2 | U12: 13 | V12: #N/A
A13: Andres Jarquin | B13: Advanced | C13: Ian Plamondon | D13: 45876 | E13: 30 | F13: 30.88 | G13: 1.0292 | H13: 38 | I13: 37.25 | J13: 0.9803 | K13: 0.235 | L13: 0.97435897 | M13: 0.98666667 | N13: 0/1 | O13: 0.15789474 | P13: 2 | Q13: 9.5 | R13: 17 | T13: 4 | U13: 34
A14: Andrew Brown | B14: Distinguished | C14: Ian Plamondon | D14: 44218 | E14: 30 | F14: 26.13 | G14: 0.8708 | H14: 38 | I14: 53.5 | J14: 1.4079 | K14: 0.1173 | L14: 0.89830508 | M14: 0.98924731 | N14: 2/2 | O14: 0.66666667 | R14: 6 | T14: 5 | U14: 25 | V14: 4
A15: Andrew Gehlot | B15: Premium | C15: Jessica Milner | D15: 42825 | E15: 30 | F15: 14.25 | G15: 0.475 | H15: 38 | I15: 33.88 | J15: 0.8914 | K15: 0.2666 | L15: 0.96875 | M15: 0.94230769 | N15: 1/1 | O15: 0.78571429 | R15: 3 | S15: 11 | T15: 1 | U15: 16 | V15: #N/A
A16: Anna Gilbert | B16: Distinguished | C16: Kristin Haase-Alvey | D16: 45294 | E16: 12 | F16: 5.5 | G16: 0.4583 | H16: 16 | I16: 14 | J16: 0.875 | K16: 0.0476 | L16: 1 | M16: 1 | N16: 1/1 | O16: 1 | R16: 1 | T16: 1 | U16: 7 | V16: #N/A
A17: Armand Brouty | B17: Distinguished | C17: Ian Plamondon | D17: 44015 | E17: 30 | F17: 24.63 | G17: 0.8208 | H17: 38 | I17: 61.44 | J17: 1.6168 | K17: 0.1675 | L17: 1 | M17: 0.95698925 | N17: 7/7 | O17: 0.86666667 | R17: 5 | T17: 8 | U17: 22 | V17: 4.4
A18: Aryan Jazayeri | B18: Premium | C18: Kristin Haase-Alvey | D18: 44260 | E18: 20 | F18: 13.75 | G18: 0.6875 | H18: 24 | I18: 22.38 | J18: 0.9323 | K18: 0.028 | L18: 1 | M18: 1 | O18: 0.36363636 | R18: 3 | T18: 1 | U18: 11 | V18: #N/A
A19: Ashley Lang | B19: Advanced | C19: Ela Cross | D19: 45261 | E19: 30 | F19: 28.75 | G19: 0.9583 | H19: 38 | I19: 38.88 | J19: 1.023 | K19: 0.1466 | L19: 1 | M19: 0.98666667 | O19: 0.28571429 | P19: 2 | Q19: 5.5 | R19: 8 | T19: 0 | U19: 26
A20: Ashley Scorsone | B20: Premium | C20: Geoff St. Marie | D20: 42909 | E20: 35 | F20: 28.13 | G20: 0.8036 | H20: 43 | I20: 53.13 | J20: 1.2355 | K20: 0.1479 | L20: 0.890625 | M20: 0.91463415 | N20: 2/3 | O20: 0.96 | P20: 1 | Q20: 10 | R20: 14 | S20: 1 | T20: 4 | U20: 29 | V20: 3.1538462
A21: Ayman Smoot | B21: Advanced | C21: Annelies de Groot | D21: 45225 | E21: 12 | F21: 18.13 | G21: 1.5104 | H21: 16 | I21: 34.06 | J21: 2.1289 | K21: 0.4398 | L21: 0.85714286 | M21: 0.90140845 | N21: 3/5 | O21: 0.6 | R21: 5 | T21: 6 | U21: 18 | V21: #N/A
A22: Ben Chamberlain | B22: Advanced | C22: Nikki Pencak | D22: 45967 | E22: 35 | F22: 6.13 | G22: 0.175 | H22: 43 | I22: 29.38 | J22: 0.6831 | K22: 0.4418 | L22: 0.76923077 | M22: 0.95833333 | N22: 4/6 | T22: 11 | U22: 11
A23: Ben Taylor | B23: Premium | C23: Jessica Milner | D23: 44281 | E23: 30 | F23: 15.06 | G23: 0.5021 | H23: 38 | I23: 40.19 | J23: 1.0576 | K23: 0.1236 | L23: 1 | M23: 1 | O23: 1 | R23: 3 | T23: 0 | U23: 13 | V23: #N/A
A24: Brandon Engle | B24: Advanced | C24: Annelies de Groot | D24: 45853 | E24: 35 | F24: 22.25 | G24: 0.6357 | H24: 43 | I24: 46.42 | J24: 1.0795 | K24: 0.2936 | L24: 0.96610169 | M24: 0.98809524 | N24: 0/1 | O24: 0.33333333 | P24: 2 | Q24: 10 | R24: 8 | T24: 1 | U24: 30 | V24: #N/A
A25: Brandon Lora | B25: Advanced | C25: Annelies de Groot | D25: 45944 | E25: 30 | F25: 24.5 | G25: 0.8167 | H25: 38 | I25: 41.56 | J25: 1.0938 | K25: 0.188 | L25: 0.98387097 | M25: 0.98924731 | N25: 4/10 | O25: 0.33333333 | R25: 0 | T25: 20 | U25: 25 | V25: #N/A
A26: Brenna Hubnik | B26: Advanced | C26: Annelies de Groot | D26: 45194 | E26: 12 | F26: 15.13 | G26: 1.2604 | H26: 16 | I26: 19.31 | J26: 1.207 | K26: 0.2454 | L26: 1 | M26: 1 | N26: 2/2 | O26: 0.78571429 | P26: 3 | Q26: 10 | R26: 4 | T26: 3 | U26: 20 | V26: #N/A
A27: Brian Cohen | B27: Premium | C27: Jessica Milner | D27: 43536 | E27: 12 | F27: 6.38 | G27: 0.5313 | H27: 16 | I27: 16.44 | J27: 1.0273 | K27: 0.1737 | L27: 0.95 | M27: 1 | O27: 1 | R27: 2 | T27: 1 | U27: 9 | V27: #N/A
A28: Brian James | B28: Advanced | C28: Annelies de Groot | D28: 45264 | E28: 30 | F28: 38.5 | G28: 1.2833 | H28: 38 | I28: 41.88 | J28: 1.102 | K28: 0.1449 | L28: 0.98019802 | M28: 0.98816568 | N28: 1/1 | O28: 0.80645161 | P28: 2 | Q28: 10 | R28: 13 | S28: 3 | T28: 6 | U28: 38 | V28: #N/A
A29: Brock Dilley | B29: Advanced | C29: Nikki Pencak | D29: 45992 | E29: 35 | H29: 43 | T29: 0 | U29: 0
A30: Bryant Salinas | B30: Premium | C30: Jessica Milner | D30: 43363 | E30: 30 | F30: 22.5 | G30: 0.75 | H30: 38 | I30: 36 | J30: 0.9474 | K30: 0.2185 | L30: 0.87234043 | M30: 0.94047619 | N30: 2/4 | O30: 0.71428571 | P30: 1 | Q30: 5 | R30: 0 | S30: 4 | T30: 6 | U30: 19 | V30: #N/A
A31: Cait White | B31: Premium | C31: Ela Cross | D31: 43903 | E31: 12 | F31: 5 | G31: 0.4167 | H31: 16 | I31: 16.5 | J31: 1.0313 | L31: 1 | M31: 1 | N31: 1/1 | O31: 1 | T31: 1 | U31: 3 | V31: #N/A
A32: Cameron Hojecki | B32: Advanced | C32: Katherine Marino | D32: 45958 | E32: 20 | F32: 8.63 | G32: 0.4313 | H32: 24 | I32: 22.88 | J32: 0.9531 | K32: 0.9218 | L32: 0.95454545 | M32: 1 | N32: 10/10 | R32: 3 | S32: 2 | T32: 14 | U32: 14
A33: Camryn To | B33: Distinguished | C33: Kristin Haase-Alvey | D33: 45261 | E33: 12 | F33: 10.25 | G33: 0.8542 | H33: 16 | I33: 19.06 | J33: 1.1914 | K33: 0.1111 | L33: 1 | M33: 1 | O33: 1 | R33: 6 | T33: 0 | U33: 10 | V33: #N/A
A34: Cara Rabaev (McLaughlin) | B34: Distinguished | C34: Ian Plamondon | D34: 45197 | E34: 30 | F34: 22 | G34: 0.7333 | H34: 38 | I34: 44.31 | J34: 1.1661 | K34: 0.315 | L34: 1 | M34: 0.87209302 | N34: 1/7 | O34: 1 | R34: 4 | T34: 13 | U34: 32 | V34: 5
A35: Carina Shanahan | B35: Advanced | C35: Kristin Haase-Alvey | D35: 45757 | E35: 30 | F35: 31.5 | G35: 1.05 | H35: 38 | I35: 36.69 | J35: 0.9655 | K35: 0.1351 | L35: 0.97590361 | M35: 0.95238095 | N35: 4/4 | O35: 0.7 | P35: 1 | Q35: 10 | R35: 6 | T35: 6 | U35: 35 | V35: #N/A
A36: Casey Young | B36: Advanced | C36: Ela Cross | D36: 45786 | E36: 35 | F36: 30.88 | G36: 0.8821 | H36: 43 | I36: 38.5 | J36: 0.8953 | K36: 0.1572 | L36: 0.98039216 | M36: 0.98780488 | N36: 3/5 | O36: 1 | R36: 14 | T36: 6 | U36: 43 | V36: #N/A
A37: Cayden Koselak | B37: Advanced | C37: Katherine Marino | D37: 45992 | E37: 35 | H37: 43 | T37: 0 | U37: 0
A38: Cesar Moreno | B38: Advanced | C38: Ela Cross | D38: 45902 | E38: 30 | F38: 31.88 | G38: 1.0625 | H38: 38 | I38: 42.38 | J38: 1.1151 | K38: 0.3486 | L38: 0.96969697 | M38: 0.99236641 | N38: 11/11 | O38: 0.92857143 | R38: 10 | T38: 27 | U38: 49 | V38: #N/A
A39: Charlie Anderson | B39: Advanced | C39: Annelies de Groot | D39: 45684 | E39: 30 | F39: 35.38 | G39: 1.1792 | H39: 38 | I39: 40.69 | J39: 1.0707 | K39: 0.2412 | L39: 1 | M39: 0.98461538 | N39: 6/6 | O39: 0.96296296 | R39: 14 | T39: 10 | U39: 39 | V39: #N/A
A40: Chazlee Myers | B40: Advanced | C40: Ian Plamondon | D40: 45666 | E40: 30 | F40: 26.75 | G40: 0.8917 | H40: 38 | I40: 36 | J40: 0.9474 | K40: 0.2339 | L40: 0.91549296 | M40: 0.85981308 | N40: 0/5 | O40: 0.66666667 | P40: 1 | Q40: 10 | R40: 9 | T40: 5 | U40: 23 | V40: 4
...

Sheet MasterTutor
A1: Full Name | B1: Faculty Leader | C1: Professional/Adjunct | D1: Tier | E1: Preferred Pronouns
A2: Aaron Schneberger | B2: Ian Plamondon | C2: Adjunct | D2: Advanced | E2: He/Him/His
A3: Akeema Williams | B3: Ian Plamondon | C3: Professional | D3: Advanced | E3: She/Her/Hers
A4: Alex Small | B4: Ela Cross | C4: Adjunct | D4: Premium | E4: He/Him/His
A5: Alexa Pinera | B5: Ian Plamondon | C5: Professional | D5: Premium | E5: She/Her/Hers
A6: Alexandra Berrios | B6: Kristin Haase-Alvey | C6: Adjunct | D6: Advanced | E6: She/Her/Hers
A7: Alexis Boucher | B7: Ian Plamondon | C7: Professional | D7: Distinguished | E7: She/Her/Hers
A8: Alison Trumbull | B8: Geoff St. Marie | C8: Adjunct | D8: Premium | E8: She/Her/Hers
A9: Allison Peck | B9: Kristin Haase-Alvey | C9: Adjunct | D9: Distinguished | E9: She/Her/Hers
A10: Amber Maldonado | B10: Annelies de Groot | C10: Professional | D10: Advanced | E10: She/Her/Hers
A11: Amelia Sain | B11: Jessica Milner | C11: Professional | D11: Premium | E11: She/Her/Hers
A12: Ana Heiser | B12: Kristin Haase-Alvey | C12: Professional | D12: Distinguished | E12: She/Her/Hers
... A201: Zoe Shanley | B201: Ian Plamondon | C201: Professional | D201: Advanced | E201: She/Her/Hers

Sheet AnnualReview
A1: id | B1: tutor_name | C1: tier | D1: fl | E1: hire_date | F1: delivery_target | G1: sessions_on_time | H1: prep_time | I1: weighted_repurchase | J1: number_of_nps | K1: average_nps | L1: current_sci | M1: availability_percent | N1: delivery_percent
A2: 3547 | B2: Aaron Schneberger | C2: Advanced | D2: Ian Plamondon | E2: 45524 | F2: 12 | G2: 0.997543 | H2: 0.1662 | J2: 7 | K2: 10 | L2: 93 | M2: 1.8404 | N2: =AVERAGEIF(MonthlyMetric!A:A,AnnualReview!B2,MonthlyMetric!F:F) -> 0.92094167
A3: 3544 | B3: Akeema Williams | C3: Advanced | D3: Ian Plamondon | E3: 45519 | F3: 30 | G3: 0.99690594 | H3: 0.1694 | J3: 10 | K3: 9.8 | L3: 24 | M3: 1.1121 | N3: =AVERAGEIF(MonthlyMetric!A:A,AnnualReview!B3,MonthlyMetric!F:F) -> 0.89430833
A4: 2535 | B4: Alex Small | C4: Premium | D4: Ela Cross | E4: 43907 | F4: 12 | G4: 1 | H4: 0.1207 | J4: 2 | K4: 9 | L4: 122 | M4: 1.1063 | N4: =AVERAGEIF(MonthlyMetric!A:A,AnnualReview!B4,MonthlyMetric!F:F) -> 0.68573333
A5: 2464 | B5: Alexa Pinera | C5: Premium | D5: Ian Plamondon | E5: 43812 | F5: 30 | G5: 0.97491349 | H5: 0.0509 | J5: 6 | K5: 8.8333 | L5: 54 | M5: 1.69 | N5: =AVERAGEIF(MonthlyMetric!A:A,AnnualReview!B5,MonthlyMetric!F:F) -> 0.837975
A6: 3614 | B6: Alexandra Berrios | C6: Advanced | D6: Kristin Haase-Alvey | E6: 45755 | F6: 12 | G6: 0.98913043 | H6: 0.1417 | J6: 1 | K6: 10 | L6: 42 | M6: 1.1815 | N6: =AVERAGEIF(MonthlyMetric!A:A,AnnualReview!B6,MonthlyMetric!F:F) -> 0.95271111
A7: 2421 | B7: Alexis Boucher | C7: Distinguished | D7: Ian Plamondon | E7: 43749 | F7: 30 | G7: 0.99692938 | H7: 0.0731 | J7: 7 | K7: 8.8571 | L7: 47 | M7: 0.9696 | N7: =AVERAGEIF(MonthlyMetric!A:A,AnnualReview!B7,MonthlyMetric!F:F) -> 0.74506667
A8: 44 | B8: Alison Trumbull | C8: Premium | D8: Geoff St. Marie | E8: 39309 | F8: 12 | G8: 0.97185741 | H8: 0.1199 | J8: 4 | K8: 9.75 | L8: 39 | M8: 1.0586 | N8: =AVERAGEIF(MonthlyMetric!A:A,AnnualReview!B8,MonthlyMetric!F:F) -> 1.0383333
A9: 3289 | B9: Allison Peck | C9: Distinguished | D9: Kristin Haase-Alvey | E9: 45223 | F9: 12 | G9: 1 | H9: 0.2278 | J9: 1 | K9: 7 | L9: 44 | M9: 1.0621 | N9: =AVERAGEIF(MonthlyMetric!A:A,AnnualReview!B9,MonthlyMetric!F:F) -> 0.47675
A10: 3569 | B10: Amber Maldonado | C10: Advanced | D10: Annelies de Groot | E10: 45683 | F10: 30 | G10: 0.86458333 | H10: 0.4987 | J10: 12 | K10: 10 | L10: 12 | M10: 1.0231 | N10: =AVERAGEIF(MonthlyMetric!A:A,AnnualReview!B10,MonthlyMetric!F:F) -> 0.71
A11: 2240 | B11: Amelia Sain | C11: Premium | D11: Jessica Milner | E11: 43479 | F11: 30 | G11: 0.99748111 | H11: 0.1023 | J11: 5 | K11: 9.4 | L11: 33 | M11: 1.2094 | N11: =AVERAGEIF(MonthlyMetric!A:A,AnnualReview!B11,MonthlyMetric!F:F) -> 0.59923333
A12: 3550 | B12: Ana Heiser | C12: Distinguished | D12: Kristin Haase-Alvey | E12: 45538 | F12: 30 | G12: 0.97610063 | H12: 0.1723 | J12: 5 | K12: 10 | L12: 38 | M12: 0.9598 | N12: =AVERAGEIF(MonthlyMetric!A:A,AnnualReview!B12,MonthlyMetric!F:F) -> 0.79215
A13: 3665 | B13: Andres Jarquin | C13: Advanced | D13: Ian Plamondon | E13: 45876 | F13: 30 | G13: 0.99135447 | H13: 0.1942 | J13: 2 | K13: 10 | L13: 50 | M13: 0.9521 | N13: =AVERAGEIF(MonthlyMetric!A:A,AnnualReview!B13,MonthlyMetric!F:F) -> 0.9964
... A21: 3306 | B21: Ayman Smoot | C21: Advanced | D21: Annelies de Groot | E21: 45225 | F21: 12 | G21: 0.95430108 | H21: 0.3755 | J21: 7 | K21: 8.5714 | L21: 5 | M21: 2.0529 | N21: =AVERAGEIF(MonthlyMetric!A:A,AnnualReview!B21,MonthlyMetric!F:F) -> 1.27915
A22: 3696 | B22: Ben Chamberlain | C22: Advanced | D22: Nikki Pencak | E22: 45967 | F22: 35 | L22: 8 | M22: 0.1221 | N22: =AVERAGEIF(MonthlyMetric!A:A,AnnualReview!B22,MonthlyMetric!F:F) -> 0.18
A23: 2851 | B23: Ben Taylor | C23: Premium | D23: Jessica Milner | E23: 44281 | F23: 30 | G23: 1 | H23: 0.1544 | J23: 5 | K23: 10 | L23: 114 | M23: 1.1478 | N23: =AVERAGEIF(MonthlyMetric!A:A,AnnualReview!B23,MonthlyMetric!F:F) -> 0.77760833
A24: 3654 | B24: Brandon Engle | C24: Advanced | D24: Annelies de Groot | E24: 45853 | F24: 35 | G24: 0.99759615 | H24: 0.3459 | J24: 5 | K24: 9.4 | L24: 22 | M24: 1.026 | N24: =AVERAGEIF(MonthlyMetric!A:A,AnnualReview!B24,MonthlyMetric!F:F) -> 0.84375
A25: 3686 | B25: Brandon Lora | C25: Advanced | D25: Nikki Pencak | E25: 45944 | F25: 30 | G25: 1 | H25: 0.2031 | L25: 8 | M25: 1.0181 | N25: =AVERAGEIF(MonthlyMetric!A:A,AnnualReview!B25,MonthlyMetric!F:F) -> 0.4628
A26: 3157 | B26: Brenna Hubnik | C26: Advanced | D26: Annelies de Groot | E26: 45194 | F26: 12 | G26: 0.99728507 | H26: 0.2076 | J26: 3 | K26: 10 | L26: 4 | M26: 1.3537 | N26: =AVERAGEIF(MonthlyMetric!A:A,AnnualReview!B26,MonthlyMetric!F:F) -> 1.238025
A27: 2309 | B27: Brian Cohen | C27: Premium | D27: Jessica Milner | E27: 43536 | F27: 12 | G27: 0.98557692 | H27: 0.2473 | J27: 3 | K27: 10 | L27: 58 | M27: 0.9982 | N27: =AVERAGEIF(MonthlyMetric!A:A,AnnualReview!B27,MonthlyMetric!F:F) -> 0.749375
A28: 3351 | B28: Brian James | C28: Advanced | D28: Annelies de Groot | E28: 45264 | F28: 30 | G28: 0.99631506 | H28: 0.1055 | J28: 20 | K28: 9.5 | L28: 46 | M28: 1.2711 | N28: =AVERAGEIF(MonthlyMetric!A:A,AnnualReview!B28,MonthlyMetric!F:F) -> 1.328475
A29: 2140 | B29: Bryant Salinas | C29: Premium | D29: Jessica Milner | E29: 43363 | F29: 30 | G29: 0.96080508 | H29: 0.1641 | J29: 8 | K29: 10 | L29: 165 | M29: 0.9718 | N29: =AVERAGEIF(MonthlyMetric!A:A,AnnualReview!B29,MonthlyMetric!F:F) -> 0.7
A30: 2528 | B30: Cait White | C30: Premium | D30: Ela Cross | E30: 43903 | F30: 12 | G30: 1 | H30: 0.0614 | L30: 75 | M30: 1.1317 | N30: =AVERAGEIF(MonthlyMetric!A:A,AnnualReview!B30,MonthlyMetric!F:F) -> 0.33770833
A31: 3690 | B31: Cameron Hojecki | C31: Advanced | D31: Katherine Marino | E31: 45958 | F31: 20 | L31: 0 | M31: 0.5938 | N31: =AVERAGEIF(MonthlyMetric!A:A,AnnualReview!B31,MonthlyMetric!F:F) -> 0.215
A32: 3339 | B32: Camryn To | C32: Distinguished | D32: Kristin Haase-Alvey | E32: 45261 | F32: 12 | G32: 0.99260355 | H32: 0.1093 | J32: 5 | K32: 9 | L32: 43 | M32: 1.1949 | N32: =AVERAGEIF(MonthlyMetric!A:A,AnnualReview!B32,MonthlyMetric!F:F) -> 0.99979167
A33: 3196 | B33: Cara Rabaev (McLaughlin) | C33: Distinguished | D33: Ian Plamondon | E33: 45197 | F33: 30 | G33: 0.90899471 | H33: 0.1256 | J33: 12 | K33: 9.9166 | L33: 169 | M33: 1.3064 | N33: =AVERAGEIF(MonthlyMetric!A:A,AnnualReview!B33,MonthlyMetric!F:F) -> 1.1781917
A34: 3615 | B34: Carina Shanahan | C34: Advanced | D34: Kristin Haase-Alvey | E34: 45757 | F34: 30 | G34: 0.98526316 | H34: 0.1792 | J34: 4 | K34: 8.75 | L34: 41 | M34: 0.747 | N34: =AVERAGEIF(MonthlyMetric!A:A,AnnualReview!B34,MonthlyMetric!F:F) -> 0.63333333
A35: 3632 | B35: Casey Young | C35: Advanced | D35: Ela Cross | E35: 45786 | F35: 35 | G35: 0.98156028 | H35: 0.3084 | J35: 4 | K35: 9.5 | L35: 23 | M35: 1.0317 | N35: =AVERAGEIF(MonthlyMetric!A:A,AnnualReview!B35,MonthlyMetric!F:F) -> 0.72337143
A36: 3676 | B36: Cesar Moreno | C36: Advanced | D36: Ela Cross | E36: 45902 | F36: 30 | G36: 0.99270073 | H36: 0.3676 | L36: 37 | M36: 0.9971 | N36: =AVERAGEIF(MonthlyMetric!A:A,AnnualReview!B36,MonthlyMetric!F:F) -> 0.76693333
A37: 3571 | B37: Charlie Anderson | C37: Advanced | D37: Annelies de Groot | E37: 45684 | F37: 30 | G37: 0.99463519 | H37: 0.133 | J37: 12 | K37: 9.5 | L37: 30 | M37: 1.0597 | N37: =AVERAGEIF(MonthlyMetric!A:A,AnnualReview!B37,MonthlyMetric!F:F) -> 0.87227273
A38: 3562 | B38: Chazlee Myers | C38: Advanced | D38: Ian Plamondon | E38: 45667 | F38: 30 | G38: 0.87925357 | H38: 0.2739 | J38: 9 | K38: 9.8888 | L38: 54 | M38: 0.9882 | N38: =AVERAGEIF(MonthlyMetric!A:A,AnnualReview!B38,MonthlyMetric!F:F) -> 0.74
A39: 918 | B39: Cheryl Lambert | C39: Premium | D39: Kristin Haase-Alvey | E39: 41246 | F39: 12 | G39: 0.98660714 | H39: 0.1234 | L39: 73 | M39: 1.0167 | N39: =AVERAGEIF(MonthlyMetric!A:A,AnnualReview!B39,MonthlyMetric!F:F) -> 0.40916667
A40: 2526 | B40: Chris Prouty | C40: Premium | D40: Annelies de Groot | E40: 43903 | F40: 20 | G40: 0.98958333 | H40: 0.3103 | J40: 5 | K40: 10 | L40: 107 | M40: 1.0012 | N40: =AVERAGEIF(MonthlyMetric!A:A,AnnualReview!B40,MonthlyMetric!F:F) -> 0.83248333
A41: 2243 | B41: Christian Collins | C41: Premium | D41: Jessica Milner | E41: 43479 | F41: 30 | G41: 0.99461279 | H41: 0.0932 | J41: 9 | K41: 10 | L41: 57 | M41: 1.3014 | N41: =AVERAGEIF(MonthlyMetric!A:A,AnnualReview!B41,MonthlyMetric!F:F) -> 1.0586083
A42: 3431 | B42: Christian Steiner | C42: Advanced | D42: Kristin Haase-Alvey | E42: 45282 | F42: 30 | G42: 0.91369606 | H42: 0.1702 | J42: 9 | K42: 10 | L42: 96 | M42: 0.9247 | N42: =AVERAGEIF(MonthlyMetric!A:A,AnnualReview!B42,MonthlyMetric!F:F) -> 0.84819167
A43: 1158 | B43: Christina Hayes | C43: Premium | D43: Jessica Milner | E43: 42576 | F43: 30 | G43: 0.99791883 | H43: 0.1276 | J43: 4 | K43: 9.5 | L43: 42 | M43: 1.0483 | N43: =AVERAGEIF(MonthlyMetric!A:A,AnnualReview!B43,MonthlyMetric!F:F) -> 0.678125
A44: 2204 | B44: Christine Santos | C44: Premium | D44: Ela Cross | E44: 43441 | F44: 12 | G44: 0.90184049 | H44: 0.1118 | J44: 1 | K44: 10 | L44: 78 | M44: 1.3783 | N44: =AVERAGEIF(MonthlyMetric!A:A,AnnualReview!B44,MonthlyMetric!F:F) -> 1.0261083
A45: 3456 | B45: Clark Howard | C45: Advanced | D45: Ela Cross | E45: 45289 | F45: 30 | G45: 0.92429022 | H45: 0.1084 | J45: 10 | K45: 4.6 | L45: 66 | M45: 0.984 | N45: =AVERAGEIF(MonthlyMetric!A:A,AnnualReview!B45,MonthlyMetric!F:F) -> 0.80035
A46: 3609 | B46: Colin Cody | C46: Advanced | D46: Ela Cross | E46: 45750 | F46: 30 | G46: 0.90942472 | H46: 0.3721 | J46: 4 | K46: 8.5 | L46: 26 | M46: 1.0915 | N46: =AVERAGEIF(MonthlyMetric!A:A,AnnualReview!B46,MonthlyMetric!F:F) -> 0.71564444
A47: 3584 | B47: Cristina Ascenzi Pettenuzzo | C47: Advanced | D47: Ian Plamondon | E47: 45702 | F47: 30 | G47: 0.9888424 | H47: 0.2348 | J47: 7 | K47: 8.8571 | L47: 72 | M47: 0.9071 | N47: =AVERAGEIF(MonthlyMetric!A:A,AnnualReview!B47,MonthlyMetric!F:F) -> 0.74542
...

Sheet SubjectAddition
A1: emp_id | B1: tutor_name | C1: category | D1: subject | E1: created | F1: subject_sci
A2: 3583 | B2: Jesse Squires | C2: Computer Science | D2: AP Computer Science A | E2: 45709.542 | F2: 5
A3: 3456 | B3: Clark Howard | C3: International Baccalaureate | D3: IB Spanish | E3: 45629.368 | F3: 5
A4: 3583 | B4: Jesse Squires | C4: Computer Science | D4: AP Computer Science Principles | E4: 45709.542 | F4: 5
A5: 3185 | B5: Rachel Daku | C5: International Baccalaureate | D5: IB Biology | E5: 45631.295 | F5: 5
A6: 3597 | B6: Tom Pluth | C6: Computer Science | D6: AP Computer Science Principles | E6: 45838.374 | F6: 5
A7: 3403 | B7: Luc Freiburg | C7: International Baccalaureate | D7: IB Computer Science | E7: 45635.51 | F7: 5
A8: 3649 | B8: Ryan Cauwenberghs | C8: Language | D8: French (College-Level) | E8: 45853.617 | F8: 5
A9: 3544 | B9: Akeema Williams | C9: Science | D9: AP Chemistry | E9: 45659.351 | F9: 5
A10: 3636 | B10: Greg Carroll | C10: Math | D10: Calculus (College-Level) | E10: 45897.726 | F10: 5
A11: 3196 | B11: Cara Rabaev (McLaughlin) | C11: International Baccalaureate | D11: IB Spanish | E11: 45668.363 | F11: 5
A12: 3670 | B12: Zoe Shanley | C12: Math | D12: Calculus (College-Level) | E12: 45911.378 | F12: 5
A13: 3568 | B13: Zack Anthony | C13: Science | D13: AP Chemistry | E13: 45684.499 | F13: 5
... A1970: 3654 | B1970: Brandon Engle | C1970: Presentation Topic | D1970: ACT 101 | E1970: 45962.25 | F1970: 0
